Workbook

Sheet 1m_15%
C5: Battery Sizing
A6: Pot _ 100% [kW] | B6: Use Time | C6: Time | D6: Pot [%] | E6: Pot_nom[kW] | F6: Energy Batt [kWh]
A7: 3650 | B7: 0.5 | C7: 8 | D7: 0 | E7: =2*1825*D7 -> 0 | F7: =E7*$B$7 -> 0
C8: 8.5 | D8: 0 | E8: =2*1825*D8 -> 0 | F8: =E8*$B$7 -> 0
C9: 9 | D9: 0.05 | E9: =2*1825*D9 -> 182.5 | F9: =E9*$B$7 -> 91.25 | G9: =(E9*1000)/780 -> 233.97436
C10: 9.5 | D10: 0.05 | E10: =2*1825*D10 -> 182.5 | F10: =E10*$B$7 -> 91.25
C11: 10 | D11: 0.25 | E11: =2*1825*D11 -> 912.5 | F11: =E11*$B$7*0 -> 0
C12: 10.5 | D12: 0.25 | E12: =2*1825*D12 -> 912.5 | F12: =E12*$B$7*0 -> 0
C13: 11 | D13: 0.35 | E13: =2*1825*D13 -> 1277.5 | F13: 0
C14: 11.5 | D14: 0.55 | E14: =2*1825*D14 -> 2007.5 | F14: 0
C15: 12 | D15: 0.95 | E15: =2*1825*D15 -> 3467.5 | F15: 0
C16: 12.5 | D16: 0.55 | E16: =2*1825*D16 -> 2007.5 | F16: 0
C17: 13 | D17: 0.55 | E17: =2*1825*D17 -> 2007.5 | F17: 0
C18: 13.5 | D18: 0.35 | E18: =2*1825*D18 -> 1277.5 | F18: 0
C19: 14 | D19: 0.25 | E19: =2*1825*D19 -> 912.5 | F19: =E19*$B$7*0 -> 0
C20: 14.5 | D20: 0.25 | E20: =2*1825*D20 -> 912.5 | F20: =E20*$B$7*0 -> 0
C21: 15 | D21: 0.15 | E21: =2*1825*D21 -> 547.5 | F21: =E21*$B$7 -> 273.75 | G21: =(E21*1000)/780 -> 701.92308 | H21: =G21-G9 -> 467.94872
C22: 15.5 | D22: 0.15 | E22: =2*1825*D22 -> 547.5 | F22: =E22*$B$7 -> 273.75
C23: 16 | D23: 0.1 | E23: =2*1825*D23 -> 365 | F23: =E23*$B$7 -> 182.5 | G23: =(E23*1000)/780 -> 467.94872 | H23: =G23-G21 -> -233.97436
C24: 16.5 | D24: 0.1 | E24: =2*1825*D24 -> 365 | F24: =E24*$B$7 -> 182.5
C25: 17 | D25: 0.05 | E25: =2*1825*D25 -> 182.5 | F25: =E25*$B$7 -> 91.25
C26: 17.5 | D26: 0.05 | E26: =2*1825*D26 -> 182.5 | F26: =E26*$B$7 -> 91.25
C27: 18 | D27: 0 | E27: =2*1825*D27 -> 0 | F27: =E27*$B$7 -> 0
C28: Total | F28: =SUM(F7:F27) -> 1277.5

Sheet 2m_15%
A3: Pot _ 100% [kW] | B3: Use Time | C3: Time | D3: Pot [%] | E3: Pot [kW] | F3: Energy Batt [kWh]
A4: 3650 | B4: 0.5 | C4: 8 | D4: 0 | E4: =2*1825*D4 -> 0 | F4: =$B$4*E4 -> 0
C5: 8.5 | D5: 0.1 | E5: =2*1825*D5 -> 365 | F5: =$B$4*E5 -> 182.5 | G5: =(E5*1000)/780 -> 467.94872
C6: 9 | D6: 0.25 | E6: =2*1825*D6 -> 912.5 | F6: =$B$4*E6*0 -> 0
C7: 9.5 | D7: 0.4 | E7: =2*1825*D7 -> 1460 | F7: 0
C8: 10 | D8: 0.95 | E8: =2*1825*D8 -> 3467.5 | F8: 0
C9: 10.5 | D9: 0.75 | E9: =2*1825*D9 -> 2737.5 | F9: 0
C10: 11 | D10: 0.35 | E10: =2*1825*D10 -> 1277.5 | F10: 0
C11: 11.5 | D11: 0.15 | E11: =2*1825*D11 -> 547.5 | F11: =$B$4*E11 -> 273.75 | G11: =(E11*1000)/780 -> 701.92308 | H11: =G11-G5 -> 233.97436
C12: 12 | D12: 0.05 | E12: =2*1825*D12 -> 182.5 | F12: =$B$4*E12 -> 91.25 | G12: =(E12*1000)/780 -> 233.97436 | H12: =G12-G11 -> -467.94872
C13: 12.5 | D13: 0 | E13: =2*1825*D13 -> 0 | F13: =$B$4*E13 -> 0
C14: 13 | D14: 0 | E14: =2*1825*D14 -> 0 | F14: =$B$4*E14 -> 0
C15: 13.5 | D15: 0 | E15: =2*1825*D15 -> 0 | F15: =$B$4*E15 -> 0
C16: 13.995357 | D16: 0.05 | E16: =2*1825*D16 -> 182.5 | F16: =$B$4*E16 -> 91.25
C17: 14.5 | D17: 0.15 | E17: =2*1825*D17 -> 547.5 | F17: =$B$4*E17 -> 273.75
C18: 14.995 | D18: 0.25 | E18: =2*1825*D18 -> 912.5 | F18: =$B$4*E18*0 -> 0
C19: 15.5 | D19: 0.35 | E19: =2*1825*D19 -> 1277.5 | F19: 0
C20: 15.994643 | D20: 0.95 | E20: =2*1825*D20 -> 3467.5 | F20: 0
C21: 16.5 | D21: 0.7 | E21: =2*1825*D21 -> 2555 | F21: 0
C22: 16.994286 | D22: 0.45 | E22: =2*1825*D22 -> 1642.5 | F22: 0
C23: 17.5 | D23: 0.3 | E23: =2*1825*D23 -> 1095 | F23: 0
C24: 17.993929 | D24: 0 | E24: =2*1825*D24 -> 0 | F24: =$B$4*E24 -> 0
C25: Total | F25: =SUM(F4:F24) -> 912.5

Sheet EnergyDemand_15%
C4: E_load | D4: Energy Required by the load profile (kWh) | E4: ='1m_15%'!F28*1.15 -> 1469.125 | G4: P_batt (kW) | H4: 600
C5: k_aging | D5: Battery Aging factor (over-sizing for end-of-life) (%) | E5: 0.8 | G5: C-rate | H5: =H4/E4 -> 0.40840636
C6: DOD_max | D6: Maximum allowable Depth of Discharge (%) | E6: 0.8
C7: n_sys | D7: System efficiency (path from the battery to propeller) (%) | E7: 0.88
C8: k_temp | D8: Temperature correction factor (-) | E8: 1.05
C9: k_c-rate | D9: Capacity rating factor (-) | E9: 1
C10: E_de | D10: Equivalent Energy Demand (kWh) | E10: =(E4*E8*E9)/(E7*E6*E5) -> 2738.9582
C11: Factor | E11: =(E8*E9)/(E5*E6*E7) -> 1.8643466
C13: E_batt_out | E13: =1470/E7 -> 1670.4545
C14: E_BOL | E14: =E13/E6 -> 2088.0682
C15: E_EOL | E15: =E14/E5 -> 2610.0852
C16: E_final | E16: =E15*E9*E8 -> 2740.5895

Sheet Batt3
B1: Ejercicio 1
B2: Nombre | C2: High Efficiency 48V 210Ah Forklift Battery
B3: Cálculo de cantidad de baterías en función de DOD ( Batt=Batt(DOD) ) | F3: Cálculo de DOD en función de Baterías ( DOD=DOD(Batt) )
B4: Tensión Banco Batt [V] | F4: Tensión Banco Batt [V]
B5: Ns máx fab (?) | C5: =2 -> 2 | F5: Ns máx fab (?) | G5: =2 -> 2
B6: V nom (modulo) | C6: 51.2 | F6: V nom (modulo) | G6: 51.2 | J6: Np | K6: Np*Ns | L6: DOD | M6: SOC
B7: Tensión Banco Batt | C7: =C5*C6 -> 102.4 | F7: Tensión Banco Batt | G7: =G5*G6 -> 102.4 | J7: 10 | K7: =2*J7 -> 20 | L7: 0.93 | M7: =1-L7 -> 0.07
J8: 12 | K8: =2*J8 -> 24 | L8: 0.78 | M8: =1-L8 -> 0.22
B9: Capacidad Banco Batt [Ah] | F9: Capacidad Banco Batt [Ah] | J9: 14 | K9: =2*J9 -> 28 | L9: 0.66 | M9: =1-L9 -> 0.34
B10: Ebatt Tot [kWh] | C10: =200 -> 200 | F10: Ebatt Tot [kWh] | G10: =200 -> 200 | J10: 16 | K10: =2*J10 -> 32 | L10: 0.58 | M10: =1-L10 -> 0.42
B11: Tensión del banco | C11: =C7 -> 102.4 | F11: Tensión del banco | G11: =G7 -> 102.4 | J11: 18 | K11: =2*J11 -> 36 | L11: 0.52 | M11: =1-L11 -> 0.48
B12: DOD | C12: 0.4 | F12: Np | G12: 32 | J12: 20 | K12: =2*J12 -> 40 | L12: 0.47 | M12: =1-L12 -> 0.53
B13: Csist requerida [Ah] | C13: =(C10*1000)/(C11*C12) -> 4882.8125 | F13: Capacidad Módulo [Ah] | G13: 210 | J13: 22 | K13: =2*J13 -> 44 | L13: 0.42 | M13: =1-L13 -> 0.58
F14: C total del banco [Ah] | G14: =G13*G12 -> 6720 | J14: 24 | K14: =2*J14 -> 48 | L14: 0.39 | M14: =1-L14 -> 0.61
B15: Cantidad de baterias en Paralelo | F15: DOD | G15: =(G10*1000)/(G11*G14) -> 0.2906436 | J15: 26 | K15: =2*J15 -> 52 | L15: 0.36 | M15: =1-L15 -> 0.64
B16: Capacidad Módulo [Ah] | C16: 210 | J16: 28 | K16: =2*J16 -> 56 | L16: 0.33 | M16: =1-L16 -> 0.67
B17: Np | C17: =C13/C16 -> 23.251488 | J17: 30 | K17: =2*J17 -> 60 | L17: 0.31 | M17: =1-L17 -> 0.69
B18: Np Real | C18: =ROUNDUP(C13/C16,0) -> 24 | J18: 32 | K18: =2*J18 -> 64 | L18: 0.29 | M18: =1-L18 -> 0.71
B19: Np máx fab (?) | C19: 10
B20: Capacidad total banco [Ah] | C20: =C16*C18 -> 5040
B22: Total de Baterías | C22: =C18*C5 -> 48 | F22: Total de Baterías | G22: =G12*G5 -> 64 | J22: Np | K22: Np*Ns | L22: Peso B_Bank [kg] | M22: Vol [cm3]
J23: 10 | K23: =2*J23 -> 20 | L23: 2100 | M23: 2493375
B24: Peso y volumen del banco | F24: Peso y volumen del banco | J24: 12 | K24: =2*J24 -> 24 | L24: 2520 | M24: 2992050
B25: Peso módulo [kg] | C25: =105 -> 105 | F25: Peso módulo [kg] | G25: =105 -> 105 | J25: 14 | K25: =2*J25 -> 28 | L25: 2940 | M25: 3490725
B26: Largo [cm] | C26: 61 | F26: Largo [cm] | G26: 61 | J26: 16 | K26: =2*J26 -> 32 | L26: 3360 | M26: 3989400
B27: Ancho [cm] | C27: 37.5 | F27: Ancho [cm] | G27: 37.5 | J27: 18 | K27: =2*J27 -> 36 | L27: 3780 | M27: 4488075
B28: Alto [cm] | C28: 54.5 | F28: Alto [cm] | G28: 54.5 | J28: 20 | K28: =2*J28 -> 40 | L28: 4200 | M28: 4986750
B29: Vol [cm3] | C29: =C26*C27*C28 -> 124668.75 | F29: Vol [cm3] | G29: =G26*G27*G28 -> 124668.75 | J29: 22 | K29: =2*J29 -> 44 | L29: 4620 | M29: 5485425
B30: Peso Total Banco [kg] | C30: =C25*C22 -> 5040 | F30: Peso Total Banco [kg] | G30: =G25*G22 -> 6720 | J30: 24 | K30: =2*J30 -> 48 | L30: 5040 | M30: 5984100
B31: Volumen Total Banco [cm3] | C31: =C29*C22 -> 5984100 | F31: Volumen Total Banco [cm3] | G31: =G29*G22 -> 7978800 | J31: 26 | K31: =2*J31 -> 52 | L31: 5460 | M31: 6482775
J32: 28 | K32: =2*J32 -> 56 | L32: 5880 | M32: 6981450
J33: 30 | K33: =2*J33 -> 60 | L33: 6300 | M33: 7480125
J34: 32 | K34: =2*J34 -> 64 | L34: 6720 | M34: 7978800
B35: Ejercicio 2
D36: Ubp [V] (Battery pack voltage) | E36: 150
D37: Ubc [V] (Baterry cell voltage) | E37: 51.2
D38: Ncs [-] (Number of cell in string) | E38: =ROUNDUP(E36/E37,0) -> 3 | K38: Np*Ns | L38: Vol [cm3]
D39: Ebc [Wh] (Energy of a baterry cell) | E39: 10752 | K39: 20 | L39: 2493375
D40: Ebs [Wh] (Energy of a String) | E40: =E39*E38 -> 32256 | K40: 24 | L40: 2992050
D41: Ebp [Wh] (Battery pack total energy) | E41: 200000 | K41: 28 | L41: 3490725
...

Sheet NMC
C3: Batería | D3: ABL-012010P | F3: Batería | G3: ABL-012030P | I3: Batería | J3: E4050T1
C4: Marca | D4: Aegis Battery | F4: Marca | G4: Aegis Battery | I4: Marca | J4: Corvus Energy
C5: Tecnología | D5: NMC | F5: Tecnología | G5: NMC | I5: Tecnología | J5: NMC
C7: Energy Density [Wh/kg] | D7: =D10/D8 -> 150 | F7: Energy Density [Wh/kg] | G7: =G10/G8 -> 171.42857 | I7: Energy Density [Wh/kg] | J7: =J23/J8 -> 898.82278
C8: Weight [kg] | D8: 0.8 | F8: Weight [kg] | G8: 2.1 | I8: Weight [kg] | J8: =J31 -> 0.47621212
C9: Energy Density [Wh/L] | D9: =D10/D15 -> 244.89796 | F9: Energy Density [Wh/L] | G9: =G10/G15 -> 319.43212 | I9: Energy Density [Wh/L] | J9: =J23/J15 -> 100.50319
C10: Energy [Wh] | D10: 120 | F10: Energy [Wh] | G10: 360
C12: Length [mm] | D12: 100 | F12: Length [mm] | G12: 230
C13: Width [mm] | D13: 70 | F13: Width [mm] | G13: 70
C14: Thickness [mm] | D14: 70 | F14: Thickness [mm] | G14: 70
C15: Volume [L] | D15: =1000*D12*D13*D14/1000000000 -> 0.49 | F15: Volume [L] | G15: =1000*G12*G13*G14/1000000000 -> 1.127 | I15: Volume [L] | J15: =J33*1000 -> 4.2588728
C19: Batería | F19: Batería | I19: Batería
C20: Ubp [V] (Battery pack voltage) | D20: 750 | F20: Ubp [V] (Battery pack voltage) | G20: 750 | I20: Ubp [V] (Battery pack voltage) | J20: 750
C21: Ubc [V] (Baterry cell voltage) | D21: 12 | F21: Ubc [V] (Baterry cell voltage) | G21: 12 | I21: Ubc [V] (Baterry cell voltage) | J21: =J20/J22 -> 2.8409091
C22: Nsc [-] (Number of cell in string) | D22: =ROUNDUP(D20/D21,0) -> 63 | F22: Nsc [-] (Number of cell in string) | G22: =ROUNDUP(G20/G21,0) -> 63 | I22: Nsc [-] (Number of cell in string) | J22: 264
C23: Ebc [Wh] (Energy of a baterry cell) | D23: =D10 -> 120 | F23: Ebc [Wh] (Energy of a baterry cell) | G23: =G10 -> 360 | I23: Ebc [Wh] (Energy of a baterry cell) | J23: =J24/J22 -> 428.0303
C24: Ebs [Wh] (Energy of a String) | D24: =D23*D22 -> 7560 | F24: Ebs [Wh] (Energy of a String) | G24: =G23*G22 -> 22680 | I24: Ebs [Wh] (Energy of a String) | J24: =226000/2 -> 113000
C25: Ebp [Wh] (Battery pack total energy) | D25: 2800000 | F25: Ebp [Wh] (Battery pack total energy) | G25: 2800000 | I25: Ebp [Wh] (Battery pack total energy) | J25: 2800000
C26: Nsb [-] (Number of strings in a battery pack) | D26: =ROUNDUP(D25/D24,0) -> 371 | F26: Nsb [-] (Number of strings in a battery pack) | G26: =ROUNDUP(G25/G24,0) -> 124 | I26: Nsb [-] (Number of strings in a battery pack) | J26: =ROUNDUP(J25/J24,0) -> 25
C27: Cbc [Ah] (Battery cell capacity) | D27: 10 | F27: Cbc [Ah] (Battery cell capacity) | G27: 30 | I27: Cbc [Ah] (Battery cell capacity) | J27: 128
C28: Cbp [Ah] (Battery pack capacity) | D28: =D27*D26 -> 3710 | F28: Cbp [Ah] (Battery pack capacity) | G28: =G27*G26 -> 3720 | I28: Cbp [Ah] (Battery pack capacity) | J28: =J27*J26 -> 3200
C29: Nbp [-] (Number of cells of the battery pack) | D29: =D22*D26 -> 23373 | F29: Nbp [-] (Number of cells of the battery pack) | G29: =G22*G26 -> 7812 | I29: Nbp [-] (Number of cells of the battery pack) | J29: =J22*J26 -> 6600
C31: mbc [kg] (mass of each battery cell) | D31: =D8 -> 0.8 | F31: mbc [kg] (mass of each battery cell) | G31: =G8 -> 2.1 | I31: mbc [kg] (mass of each battery cell) | J31: =J32/J29 -> 0.47621212
C32: mbp [kg] (battery mass pack) | D32: =D29*D31 -> 18698.4 | F32: mbp [kg] (battery mass pack) | G32: =G29*G31 -> 16405.2 | I32: mbp [kg] (battery mass pack) | J32: 3143
C33: Vbc [m3] (volume of each cell) | D33: =D15/1000 -> 0.00049 | F33: Vbc [m3] (volume of each cell) | G33: =G15/1000 -> 0.001127 | I33: Vbc [m3] (volume of each cell) | J33: =J34/J29 -> 0.0042588728
C34: Vbp [m3] (volume of the battery pack) | D34: =D29*D33 -> 11.45277 | F34: Vbp [m3] (volume of the battery pack) | G34: =G29*G33 -> 8.804124 | I34: Vbp [m3] (volume of the battery pack) | J34: =(1343*738*2836)/100000000 -> 28.10856
C36: C-rate_bcc[1/h] (continuous C-rate of the battery cell)(charge) | D36: 0.5 | F36: C-rate_bcc[1/h] (continuous C-rate of the battery cell)(charge) | G36: 0.5 | I36: C-rate_bcc[1/h] (continuous C-rate of the battery cell)(charge) | J36: 1
C37: C-rate_bcc[1/h] (continuous C-rate of the battery cell)(discharge) | D37: 1 | F37: C-rate_bcc[1/h] (continuous C-rate of the battery cell)(discharge) | G37: 1 | I37: C-rate_bcc[1/h] (continuous C-rate of the battery cell)(discharge) | J37: 1
C38: C-rate_bcp[1/h] (peak C-rate of the battery cell) | D38: 3 | F38: C-rate_bcp[1/h] (peak C-rate of the battery cell) | G38: 3 | I38: C-rate_bcp[1/h] (peak C-rate of the battery cell) | J38: 3
C39: Charge Current [A] | D39: 3 | F39: Charge Current [A] | G39: 5 | I39: Charge Current [A] | J39: =J27*J36 -> 128
C40: Constant Discharge Current [A] | D40: 5 | F40: Constant Discharge Current [A] | G40: 30 | I40: Constant Discharge Current [A] | J40: =J37*J27 -> 128
C41: Peak Discharge Current [A] @2s | D41: 20 | F41: Peak Discharge Current [A] @2s | G41: 60 | I41: Peak Discharge Current [A] @2s | J41: 750
C42: Ispc [A] (string peak current) | D42: =D41 -> 20 | F42: Ispc [A] (string peak current) | G42: =G41 -> 60 | I42: Ispc [A] (string peak current) | J42: =J41 -> 750
C43: Ibpp[A] (battery pack pack current) | D43: =D42*D26 -> 7420 | F43: Ibpp[A] (battery pack pack current) | G43: =G42*G26 -> 7440 | I43: Ibpp[A] (battery pack pack current) | J43: =J42*J26 -> 18750
C44: Pbpp [W] (battery pack peak power) | D44: =D43*D20 -> 5565000 | E44: =D44/1000 -> 5565 | F44: Pbpp [W] (battery pack peak power) | G44: =G43*G20 -> 5580000 | H44: =G44/1000 -> 5580 | I44: Pbpp [W] (battery pack peak power) | J44: =J43*J20 -> 14062500 | K44: =J44/1000 -> 14062.5
C45: Iscc [A] (string continuous current) (charge) | D45: =D39 -> 3 | F45: Iscc [A] (string continuous current) (charge) | G45: =G39 -> 5 | I45: Iscc [A] (string continuous current) (charge) | J45: =J39 -> 128
C46: Ibpc[A] (battery pack continuous current) (charge) | D46: =D45*D26 -> 1113 | F46: Ibpc[A] (battery pack continuous current) (charge) | G46: =G45*G26 -> 620 | I46: Ibpc[A] (battery pack continuous current) (charge) | J46: =J45*J26 -> 3200
C47: Pbpc[W] (battery pack continuous power) (charge) | D47: =D46*D20 -> 834750 | F47: Pbpc[W] (battery pack continuous power) (charge) | G47: =G46*G20 -> 465000 | I47: Pbpc[W] (battery pack continuous power) (charge) | J47: =J46*J20 -> 2400000
C48: Iscc [A] (string continuous current) (discharge) | D48: 5 | F48: Iscc [A] (string continuous current) (discharge) | G48: =G40 -> 30 | I48: Iscc [A] (string continuous current) (discharge) | J48: =J40 -> 128
C49: Ibpc[A] (battery pack continuous current) (discharge) | D49: =D48*D26 -> 1855 | F49: Ibpc[A] (battery pack continuous current) (discharge) | G49: =G48*G26 -> 3720 | I49: Ibpc[A] (battery pack continuous current) (discharge) | J49: =J48*J26 -> 3200
...

Sheet LFP
C3: Batería | D3: URB1270 | G3: Batería | H3: PSL-SC-12500 | K3: Batería | L3: U27-36XP
C4: Marca | D4: Ultralife | G4: Marca | H4: PowerSonic | K4: Marca | L4: Valence
C5: Tecnología | D5: LFP | G5: Tecnología | H5: LFP | K5: Tecnología | L5: LFP
C7: Energy Density [Wh/kg] | D7: 97 | G7: Energy Density [Wh/kg] | H7: =H11/H8 -> 101.5873 | K7: Energy Density [Wh/kg] | L7: 102
C8: Battery Cell Weight min [kg] | D8: 0.9 | G8: Battery Cell Weight [kg] | H8: 6.3 | K8: Battery Cell Weight [kg] | L8: 18.7
C9: Battery Cell Weight max [kg] | D9: 1.1
C10: Energy min [Wh] | D10: =D7*D8 -> 87.3
C11: Energy max [Wh] | D11: =D7*D9 -> 106.7 | G11: Energy [Wh] | H11: 640 | K11: Energy [Wh] | L11: 1920 | O11: Motor Main Diesel Cat3516B
C12: Length [mm] | D12: 152 | G12: Length [mm] | H12: 197 | K12: Length [mm] | L12: 306 | O12: Dim A (mm) | P12: 5957
C13: Width [mm] | D13: 65 | G13: Width [mm] | H13: 166 | K13: Width [mm] | L13: 172 | O13: Dim B (mm) | P13: 2286
C14: Thickness [mm] | D14: 92 | G14: Thickness [mm] | H14: 171 | K14: Thickness [mm] | L14: 225 | O14: Dim C (mm) | P14: 2494
C15: Volume [m3] | D15: =D12*D13*D14/1000000000 -> 0.00090896 | G15: Volume [L] | H15: =1000*H12*H13*H14/(1000000000) -> 5.592042 | K15: Volume [L] | L15: =1000*L12*L13*L14/(1000000000) -> 11.8422 | O15: Vdiesel (mm3) | P15: =P12*P13*P14 -> 33962548788
O16: Vdiesel (m3) | P16: 33.963
O17: Vdiesel (L) | P17: 33963
O18: mdiesel (kg) | P18: 13750
C19: Batería | G19: Batería | K19: Batería
C20: Ubp [V] (Battery pack voltage) | D20: 750 | G20: Ubp [V] (Battery pack voltage) | H20: 750 | K20: Ubp [V] (Battery pack voltage) | L20: 750 | O20: Battery Pack DAMEN ASD TUG 2810
C21: Ubc [V] (Baterry cell voltage) | D21: 12.8 | G21: Ubc [V] (Baterry cell voltage) | H21: 12.8 | K21: Ubc [V] (Baterry cell voltage) | L21: 38.4 | O21: Total number | P21: 140
C22: Nsc [-] (Number of cell in string) | D22: =ROUNDUP(D20/D21,0) -> 59 | G22: Nsc [-] (Number of cell in string) | H22: =ROUNDUP(H20/H21,0) -> 59 | K22: Nsc [-] (Number of cell in string) | L22: =ROUNDUP(L20/L21,0) -> 20 | O22: Vbatt (L) | P22: =P21*L15 -> 1657.908
C23: Ebc [Wh] (Energy of a baterry cell) | D23: 97 | G23: Ebc [Wh] (Energy of a baterry cell) | H23: =H11 -> 640 | K23: Ebc [Wh] (Energy of a baterry cell) | L23: =L11 -> 1920 | O23: mbatt( kg) | P23: =P21*L8 -> 2618
C24: Ebs [Wh] (Energy of a String) | D24: =D23*D22 -> 5723 | G24: Ebs [Wh] (Energy of a String) | H24: =H23*H22 -> 37760 | K24: Ebs [Wh] (Energy of a String) | L24: =L23*L22 -> 38400 | O24: Gen Set
C25: Ebp [Wh] (Battery pack total energy) | D25: =L25 -> 2800000 | G25: Ebp [Wh] (Battery pack total energy) | H25: =L25 -> 2800000 | K25: Ebp [Wh] (Battery pack total energy) | L25: 2800000 | O25: mgenset( kg) | P25: 2600
C26: Nsb [-] (Number of strings in a battery pack) | D26: =ROUNDUP(D25/D24,0) -> 490 | G26: Nsb [-] (Number of strings in a battery pack) | H26: =ROUNDUP(H25/H24,0) -> 75 | K26: Nsb [-] (Number of strings in a battery pack) | L26: =ROUNDUP(L25/L24,0) -> 73 | O26: Vgenset (L) | P26: 3801.63
C27: Cbc [Ah] (Battery cell capacity) | D27: 7.6 | G27: Cbc [Ah] (Battery cell capacity) | H27: 50 | K27: Cbc [Ah] (Battery cell capacity) | L27: 50
C28: Cbp [Ah] (Battery pack capacity) | D28: =D27*D26 -> 3724 | G28: Cbp [Ah] (Battery pack capacity) | H28: =H27*H26 -> 3750 | K28: Cbp [Ah] (Battery pack capacity) | L28: =L27*L26 -> 3650 | O28: Rupanco TUG
C29: Nbp [-] (Number of cells of the battery pack) | D29: =D22*D26 -> 28910 | G29: Nbp [-] (Number of cells of the battery pack) | H29: =H22*H26 -> 4425 | K29: Nbp [-] (Number of cells of the battery pack) | L29: =L22*L26 -> 1460 | O29: Gross Tonnage (L) | P29: =269*2.832*1000 -> 761808
O30: Net Tonage (L) | P30: =P29*0.3 -> 228542.4 | Q30: =P30/1000 -> 228.5424
C31: mbc [kg] (mass of each battery cell) | D31: 1 | G31: mbc [kg] (mass of each battery cell) | H31: 6.3 | K31: mbc [kg] (mass of each battery cell) | L31: 18.7 | O31: Deadweight (kg) | P31: 220000
C32: mbp [kg] (battery mass pack) | D32: =D29*D31 -> 28910 | G32: mbp [kg] (battery mass pack) | H32: =H29*H31 -> 27877.5 | K32: mbp [kg] (battery mass pack) | L32: =L29*L31 -> 27302
C33: Vbc [m3] (volume of each cell) | D33: =D15 -> 0.00090896 | G33: Vbc [m3] (volume of each cell) | H33: 0.00559 | K33: Vbc [m3] (volume of each cell) | L33: 0.01184
C34: Vbp [m3] (volume of the battery pack) | D34: =D29*D33 -> 26.278034 | G34: Vbp [m3] (volume of the battery pack) | H34: =H29*H33 -> 24.73575 | K34: Vbp [m3] (volume of the battery pack) | L34: =L29*L33 -> 17.2864
C36: C-rate_bcc[1/h] (continuous C-rate of the battery cell)(charge) | D36: =D39/D27 -> 1 | G36: C-rate_bcc[1/h] (continuous C-rate of the battery cell)(charge) | H36: =H39/H27 -> 1 | K36: C-rate_bcc[1/h] (continuous C-rate of the battery cell)(charge) | L36: =L39/L27 -> 1
C37: C-rate_bcc[1/h] (continuous C-rate of the battery cell)(discharge) | D37: =D40/D27 -> 1.9736842 | G37: C-rate_bcc[1/h] (continuous C-rate of the battery cell)(discharge) | H37: =H40/H27 -> 1 | K37: C-rate_bcc[1/h] (continuous C-rate of the battery cell)(discharge) | L37: =L40/L27 -> 1
C38: C-rate_bcp[1/h] (peak C-rate of the battery cell) | D38: =D41/D27 -> 7.2368421 | G38: C-rate_bcp[1/h] (peak C-rate of the battery cell) | H38: =H41/H27 -> 2.8 | K38: C-rate_bcp[1/h] (peak C-rate of the battery cell) | L38: =L41/L27 -> 3
C39: Charge Current [A] | D39: 7.6 | G39: Charge Current [A] | H39: 50 | K39: Charge Current [A] | L39: 50
C40: Constant Discharge Current [A] | D40: 15 | G40: Constant Discharge Current [A] | H40: 50 | K40: Constant Discharge Current [A] | L40: 50
C41: Peak Discharge Current [A] @2s | D41: 55 | G41: Peak Discharge Current [A] @2s | H41: 140 | K41: Peak Discharge Current [A] @2s | L41: 150
C42: Ispc [A] (string peak current) | D42: =D41 -> 55 | G42: Ispc [A] (string peak current) | H42: =H41 -> 140 | K42: Ispc [A] (string peak current) | L42: =L41 -> 150
C43: Ibpp[A] (battery pack pack current) | D43: =D42*D26 -> 26950 | G43: Ibpp[A] (battery pack pack current) | H43: =H42*H26 -> 10500 | K43: Ibpp[A] (battery pack pack current) | L43: =L42*L26 -> 10950
C44: Pbpp [kW] (battery pack peak power) | D44: =D43*D20/1000 -> 20212.5 | G44: Pbpp [kW] (battery pack peak power) | H44: =H43*H20/1000 -> 7875 | K44: Pbpp [kW] (battery pack peak power) | L44: =L43*L20/1000 -> 8212.5
...

Sheet LTO
C3: Batería | D3: SLB12400L151 | G3: Batería | H3: SLB08115L140 | K3: Batería | L3: ELB 1500mAh LTO
C4: Marca | D4: Nichicon | G4: Marca | H4: Nichicon | K4: Marca | L4: Eco Lotithium Battery
C5: Tecnología | D5: LTO | G5: Tecnología | H5: LTO | K5: Tecnología | L5: LTO
K6: Energy Density [Wh/L] | L6: =L11/L15 -> 212.8906
C7: Energy Density [Wh/L] | D7: 73 | G7: Energy Density [Wh/L] | H7: 58 | K7: Energy Density [Wh/kg] | L7: =L11/L8 -> 78.26087
C8: Weight [kg] | D8: 0.09 | G8: Weight [kg] | H8: 0.0012 | K8: Weight [kg] | L8: 0.046
C9: Energy Density [Wh/kg] | D9: =D10/D8 -> 4 | G9: Energy Density [Wh/Kg] | H9: =H10/H8 -> 28
C10: Energy [Wh] | D10: 0.36 | G10: Energy [Wh] | H10: =2.4*14*0.001 -> 0.0336
K11: Energy [Wh] | L11: 3.6
C12: Diam [mm] | D12: 12.5 | G12: Diam [mm] | H12: 8 | K12: Radio [mm] | L12: =18.2/2 -> 9.1
C13: Height [mm] | D13: 40 | G13: Height [mm] | H13: 11.5 | K13: Height [mm] | L13: 65
C15: Volume [L] | D15: =PI()*(D12^2)*D13/1000000 -> 0.019634954 | G15: Volume [L] | H15: =PI()*(H12^2)*H13/1000000 -> 0.0023122122 | K15: Volume [L] | L15: =PI()*(L12^2)*L13/1000000 -> 0.016910094
C19: Batería | G19: Batería | K19: Batería
C20: Ubp [V] (Battery pack voltage) | D20: 750 | G20: Ubp [V] (Battery pack voltage) | H20: 750 | K20: Ubp [V] (Battery pack voltage) | L20: 750
C21: Ubc [V] (Baterry cell voltage) | D21: =2.4 -> 2.4 | G21: Ubc [V] (Baterry cell voltage) | H21: =2.4 -> 2.4 | K21: Ubc [V] (Baterry cell voltage) | L21: =2.3 -> 2.3
C22: Nsc [-] (Number of cell in string) | D22: =ROUNDUP(D20/D21,0) -> 313 | G22: Nsc [-] (Number of cell in string) | H22: =ROUNDUP(H20/H21,0) -> 313 | K22: Nsc [-] (Number of cell in string) | L22: =ROUNDUP(L20/L21,0) -> 327
C23: Ebc [Wh] (Energy of a baterry cell) | D23: =D10 -> 0.36 | G23: Ebc [Wh] (Energy of a baterry cell) | H23: =H10 -> 0.0336 | K23: Ebc [Wh] (Energy of a baterry cell) | L23: =L11 -> 3.6
C24: Ebs [Wh] (Energy of a String) | D24: =D23*D22 -> 112.68 | G24: Ebs [Wh] (Energy of a String) | H24: =H23*H22 -> 10.5168 | K24: Ebs [Wh] (Energy of a String) | L24: =L23*L22 -> 1177.2
C25: Ebp [Wh] (Battery pack total energy) | D25: 2800000 | G25: Ebp [Wh] (Battery pack total energy) | H25: 2800000 | K25: Ebp [Wh] (Battery pack total energy) | L25: 2800000
C26: Nsb [-] (Number of strings in a battery pack) | D26: =ROUNDUP(D25/D24,0) -> 24850 | G26: Nsb [-] (Number of strings in a battery pack) | H26: =ROUNDUP(H25/H24,0) -> 266241 | K26: Nsb [-] (Number of strings in a battery pack) | L26: =ROUNDUP(L25/L24,0) -> 2379
C27: Cbc [Ah] (Battery cell capacity) | D27: 0.15 | G27: Cbc [Ah] (Battery cell capacity) | H27: 0.014 | K27: Cbc [Ah] (Battery cell capacity) | L27: 1.5
C28: Cbp [Ah] (Battery pack capacity) | D28: =D27*D26 -> 3727.5 | G28: Cbp [Ah] (Battery pack capacity) | H28: =H27*H26 -> 3727.374 | K28: Cbp [Ah] (Battery pack capacity) | L28: =L27*L26 -> 3568.5
C29: Nbp [-] (Number of cells of the battery pack) | D29: =D22*D26 -> 7778050 | G29: Nbp [-] (Number of cells of the battery pack) | H29: =H22*H26 -> 83333433 | K29: Nbp [-] (Number of cells of the battery pack) | L29: =L22*L26 -> 777933
C31: mbc [kg] (mass of each battery cell) | D31: =D8 -> 0.09 | G31: mbc [kg] (mass of each battery cell) | H31: 0.0012 | K31: mbc [kg] (mass of each battery cell) | L31: =L8 -> 0.046
C32: mbp [kg] (battery mass pack) | D32: =D29*D31 -> 700024.5 | G32: mbp [kg] (battery mass pack) | H32: =H29*H31 -> 100000.12 | K32: mbp [kg] (battery mass pack) | L32: =L29*L31 -> 35784.918
C33: Vbc [m3] (volume of each cell) | D33: =D15/1000 -> 1.9634954e-05 | G33: Vbc [m3] (volume of each cell) | H33: =H15/1000 -> 2.3122122e-06 | K33: Vbc [m3] (volume of each cell) | L33: =L15/1000 -> 1.6910094e-05
C34: Vbp [m3] (volume of the battery pack) | D34: =D29*D33 -> 152.72165 | G34: Vbp [m3] (volume of the battery pack) | H34: =H29*H33 -> 192.68458 | K34: Vbp [m3] (volume of the battery pack) | L34: =L29*L33 -> 13.15492
C36: C-rate_bcc[1/h] (continuous C-rate of the battery cell)(charge) | D36: =D39/D27 -> 1 | G36: C-rate_bcc[1/h] (continuous C-rate of the battery cell)(charge) | H36: =H39/H27 -> 1 | K36: C-rate_bcc[1/h] (continuous C-rate of the battery cell)(charge) | L36: =L39/L27 -> 2
C37: C-rate_bcc[1/h] (continuous C-rate of the battery cell)(discharge) | D37: =D40/D27 -> 1 | G37: C-rate_bcc[1/h] (continuous C-rate of the battery cell)(discharge) | H37: =H40/H27 -> 0.5 | K37: C-rate_bcc[1/h] (continuous C-rate of the battery cell)(discharge) | L37: =L40/L27 -> 1
C38: C-rate_bcp[1/h] (peak C-rate of the battery cell) | D38: =D41/D27 -> 20 | G38: C-rate_bcp[1/h] (peak C-rate of the battery cell) | H38: =H41/H27 -> 20 | K38: C-rate_bcp[1/h] (peak C-rate of the battery cell) | L38: =L41/L27 -> 8
C39: Charge Current [A] | D39: =0.15 -> 0.15 | G39: Charge Current [A] | H39: =0.014 -> 0.014 | K39: Charge Current [A] | L39: =3 -> 3
C40: Constant Discharge Current [A] | D40: =0.15 -> 0.15 | G40: Constant Discharge Current [A] | H40: =0.007 -> 0.007 | K40: Constant Discharge Current [A] | L40: =1.5 -> 1.5
C41: Peak Discharge Current [A] @2s | D41: =3 -> 3 | G41: Peak Discharge Current [A] @2s | H41: =0.28 -> 0.28 | K41: Peak Discharge Current [A] @2s | L41: =12 -> 12
C42: Ispc [A] (string peak current) | D42: =D41*1 -> 3 | G42: Ispc [A] (string peak current) | H42: =H41 -> 0.28 | K42: Ispc [A] (string peak current) | L42: =L41 -> 12
C43: Ibpp[A] (battery pack pack current) | D43: =D42*D26 -> 74550 | E43: =D43/1000 -> 74.55 | G43: Ibpp[A] (battery pack pack current) | H43: =H42*H26 -> 74547.48 | K43: Ibpp[A] (battery pack pack current) | L43: =L42*L26 -> 28548 | M43: =L43/1000 -> 28.548
C44: Pbpp [kW] (battery pack peak power) | D44: =D43*D20/1000 -> 55912.5 | E44: =D44/1000 -> 55.9125 | G44: Pbpp [kW] (battery pack peak power) | H44: =H43*H20/1000 -> 55910.61 | K44: Pbpp [kW] (battery pack peak power) | L44: =L43*L20/1000 -> 21411 | M44: =L44/1000 -> 21.411
C45: Iscc [A] (string continuous current) (charge) | D45: =D39 -> 0.15 | G45: Iscc [A] (string continuous current) (charge) | H45: =H39 -> 0.014 | K45: Iscc [A] (string continuous current) (charge) | L45: =L39 -> 3
C46: Ibpc[A] (battery pack continuous current) (charge) | D46: =D45*D26 -> 3727.5 | G46: Ibpc[A] (battery pack continuous current) (charge) | H46: =H45*H26 -> 3727.374 | K46: Ibpc[A] (battery pack continuous current) (charge) | L46: =L45*L26 -> 7137
C47: Pbpc[W] (battery pack continuous power) (charge) | D47: =D46*D20/1000 -> 2795.625 | G47: Pbpc[W] (battery pack continuous power) (charge) | H47: =H46*H20/1000 -> 2795.5305 | K47: Pbpc[W] (battery pack continuous power) (charge) | L47: =L46*L20/1000 -> 5352.75
C48: Iscc [A] (string continuous current) (discharge) | D48: =D40 -> 0.15 | G48: Iscc [A] (string continuous current) (discharge) | H48: =H40 -> 0.007 | K48: Iscc [A] (string continuous current) (discharge) | L48: =L40 -> 1.5
...

Sheet Radar_Plot
C3: Baterías NMC (LiNiMnCo02) | K3: Baterías LFP (LiFePO4) | S3: Baterías LTO (Li2TiO3) | AA3: Baterías Ion Litio | AG3: Baterías Ion Litio
D4: AEGIS1 | E4: AEGIS2 | F4: Corvus Energy | G4: NMC | L4: Ultralife | M4: PowerSonic | N4: Valence | O4: LFP | T4: Nichicon 1 | U4: Nichicon 2 | V4: ECO Lithium | W4: LTO | AB4: NMC | AC4: LFP | AD4: LTO | AE4: Avg | AH4: NMC | AI4: LFP | AJ4: Avg
C5: Ciclos de Vida | D5: 1000 | E5: 1000 | F5: 2000 | G5: =SUM(D5:F5)/3 -> 1333.3333 | K5: Ciclos de Vida | L5: 1500 | M5: 2000 | N5: 4000 | O5: =SUM(L5:N5)/3 -> 2500 | S5: Ciclos de Vida | T5: 20000 | U5: 10000 | V5: 10000 | W5: =SUM(T5:V5)/3 -> 13333.333 | AA5: Life cycles [-] | AB5: 1333.3333 | AC5: 2500 | AD5: 13333.333 | AE5: =SUM(AB5:AD5)/3 -> 5722.2222 | AG5: Life cycles [-] | AH5: 1333.3333 | AI5: 2500 | AJ5: =SUM(AH5:AI5)/2 -> 1916.6667
C6: Celdas Totales | D6: =NMC!D29 -> 23373 | E6: =NMC!G29 -> 7812 | F6: =NMC!J29 -> 6600 | G6: =SUM(D6:F6)/3 -> 12595 | K6: Celdas Totales | L6: =LFP!D29 -> 28910 | M6: =LFP!H29 -> 4425 | N6: =LFP!L29 -> 1460 | O6: =SUM(L6:N6)/3 -> 11598.333 | S6: Celdas Totales | T6: =LTO!D29 -> 7778050 | U6: =LTO!H29 -> 83333433 | V6: =LTO!L29 -> 777933 | W6: =SUM(T6:V6)/3 -> 30629805 | AA6: Cells [-] | AB6: 12595 | AC6: 11598.333 | AD6: 30629805 | AE6: =SUM(AB6:AD6)/3 -> 10218000 | AG6: Cells [-] | AH6: 12595 | AI6: 11598.333 | AJ6: =SUM(AH6:AI6)/2 -> 12096.667
C7: Weight [kg] | D7: =NMC!D32 -> 18698.4 | E7: =NMC!G32 -> 16405.2 | F7: =NMC!J32 -> 3143 | G7: =SUM(D7:F7)/3 -> 12748.867 | K7: Weight [kg] | L7: =LFP!D32 -> 28910 | M7: =LFP!H32 -> 27877.5 | N7: =LFP!L32 -> 27302 | O7: =SUM(L7:N7)/3 -> 28029.833 | S7: Weight [kg] | T7: =LTO!D32 -> 700024.5 | U7: =LTO!H32 -> 100000.12 | V7: =LTO!L32 -> 35784.918 | W7: =SUM(T7:V7)/3 -> 278603.18 | AA7: Weight [kg] | AB7: 12748.867 | AC7: 28029.833 | AD7: 278603.18 | AE7: =SUM(AB7:AD7)/3 -> 106460.63 | AG7: Weight [kg] | AH7: 12748.867 | AI7: 28029.833 | AJ7: =SUM(AH7:AI7)/2 -> 20389.35
C8: Volume [m3] | D8: =NMC!D34 -> 11.45277 | E8: =NMC!G34 -> 8.804124 | F8: =NMC!J34 -> 28.10856 | G8: =SUM(D8:F8)/3 -> 16.121818 | K8: Volume [m3] | L8: =LFP!D34 -> 26.278034 | M8: =LFP!H34 -> 24.73575 | N8: =LFP!L34 -> 17.2864 | O8: =SUM(L8:N8)/3 -> 22.766728 | S8: Volume [m3] | T8: =LTO!D34 -> 152.72165 | U8: =LTO!H34 -> 192.68458 | V8: =LTO!L34 -> 13.15492 | W8: =SUM(T8:V8)/3 -> 119.52038 | AA8: Volume [m3] | AB8: 16.121818 | AC8: 22.766728 | AD8: 119.52038 | AE8: =SUM(AB8:AD8)/3 -> 52.802977 | AG8: Volume [m3] | AH8: 16.121818 | AI8: 22.766728 | AJ8: =SUM(AH8:AI8)/2 -> 19.444273
C9: Power Discharge [kW] | D9: =NMC!D50 -> 1391.25 | E9: =NMC!G50 -> 2790 | F9: =NMC!J50 -> 2400 | G9: =SUM(D9:F9)/3 -> 2193.75 | K9: Power Discharge [kW] | L9: =LFP!D50 -> 5512.5 | M9: =LFP!H50 -> 2812.5 | N9: =LFP!L50 -> 2737.5 | O9: =SUM(L9:N9)/3 -> 3687.5 | S9: Power Discharge [kW] | T9: =LTO!D50 -> 2795.625 | U9: =LTO!H50 -> 1397.7652 | V9: =LTO!L50 -> 2676.375 | W9: =SUM(T9:V9)/3 -> 2289.9217 | AA9: Power Discharge [kW] | AB9: 2193.75 | AC9: 3687.5 | AD9: 2289.9217 | AE9: =SUM(AB9:AD9)/3 -> 2723.7239 | AG9: Power Discharge [kW] | AH9: 2193.75 | AI9: 3687.5 | AJ9: =SUM(AH9:AI9)/2 -> 2940.625
C13: Porcentajes Baterías NMC (LiNiMnCo02) | K13: Porcentajes Baterías LFP (LiFePO4) | S13: Porcentajes Baterías LTO (Li2TiO3) | AA13: Baterías Ion Litio | AG13: Baterías Ion Litio
D14: AEGIS1 | E14: AEGIS2 | F14: Corvus Energy | G14: NMC | L14: Ultralife | M14: PowerSonic | N14: Valence | O14: LFP | T14: Nichicon 1 | U14: Nichicon 2 | V14: ECO Lithium | W14: LTO | AB14: NMC | AC14: LFP | AD14: LTO | AE14: Avg | AH14: NMC | AI14: LFP | AJ14: Avg
C15: Ciclos de Vida | D15: =D5/$F$5 -> 0.5 | E15: =E5/$F$5 -> 0.5 | F15: =F5/$F$5 -> 1 | G15: =G5/$F$5 -> 0.66666667 | K15: Ciclos de Vida | L15: =L5/$N$5 -> 0.375 | M15: =M5/$N$5 -> 0.5 | N15: =N5/$N$5 -> 1 | O15: =O5/$N$5 -> 0.625 | S15: Ciclos de Vida | T15: =T5/$T$5 -> 1 | U15: =U5/$T$5 -> 0.5 | V15: =V5/$T$5 -> 0.5 | W15: =W5/$T$5 -> 0.66666667 | AA15: Life cycles [-] | AB15: =AB5/$AD$5 -> 0.1 | AC15: =AC5/$AD$5 -> 0.1875 | AD15: =AD5/$AD$5 -> 1 | AG15: Life cycles [-] | AH15: =AH5/$AI$5 -> 0.53333333 | AI15: =AI5/$AI$5 -> 1
C16: Celdas Totales | D16: =D6/$D$6 -> 1 | E16: =E6/$D$6 -> 0.33423181 | F16: =F6/$D$6 -> 0.2823771 | G16: =G6/$D$6 -> 0.53886964 | K16: Celdas Totales | L16: =L6/$L$6 -> 1 | M16: =M6/$L$6 -> 0.15306122 | N16: =N6/$L$6 -> 0.050501557 | O16: =O6/$L$6 -> 0.40118759 | S16: Celdas Totales | T16: =T6/$U$6 -> 0.093336488 | U16: =U6/$U$6 -> 1 | V16: =V6/$U$6 -> 0.0093351848 | W16: =W6/$U$6 -> 0.36755722 | AA16: Cells [-] | AB16: =AB6/$AD$6 -> 0.00041120079 | AC16: =AC6/$AD$6 -> 0.00037866167 | AD16: =AD6/$AD$6 -> 1 | AG16: Cells [-] | AH16: =AH6/$AH$6 -> 1 | AI16: =AI6/$AH$6 -> 0.92086807
C17: Weight [kg] | D17: =D7/$D$7 -> 1 | E17: =E7/$D$7 -> 0.87735849 | F17: =F7/$D$7 -> 0.16808925 | G17: =G7/$D$7 -> 0.68181591 | K17: Weight [kg] | L17: =L7/$L$7 -> 1 | M17: =M7/$L$7 -> 0.96428571 | N17: =N7/$L$7 -> 0.94437911 | O17: =O7/$L$7 -> 0.96955494 | S17: Weight [kg] | T17: =T7/$T$7 -> 1 | U17: =U7/$T$7 -> 0.14285231 | V17: =V7/$T$7 -> 0.051119522 | W17: =W7/$T$7 -> 0.39799061 | AA17: Weight [kg] | AB17: =AB7/$AD$7 -> 0.045759947 | AC17: =AC7/$AD$7 -> 0.10060845 | AD17: =AD7/$AD$7 -> 1 | AG17: Weight [kg] | AH17: =AH7/$AI$7 -> 0.45483205 | AI17: =AI7/$AI$7 -> 1
C18: Volume [m3] | D18: =D8/$F$8 -> 0.40744776 | E18: =E8/$F$8 -> 0.3132186 | F18: =F8/$F$8 -> 1 | G18: =G8/$F$8 -> 0.57355546 | K18: Volume [m3] | L18: =L8/$L$8 -> 1 | M18: =M8/$L$8 -> 0.94130902 | N18: =N8/$L$8 -> 0.657827 | O18: =O8/$L$8 -> 0.86637867 | S18: Volume [m3] | T18: =T8/$U$8 -> 0.79259926 | U18: =U8/$U$8 -> 1 | V18: =V8/$U$8 -> 0.068271783 | W18: =W8/$U$8 -> 0.62029035 | AA18: Volume [m3] | AB18: =AB8/$AD$8 -> 0.1348876 | AC18: =AC8/$AD$8 -> 0.19048406 | AD18: =AD8/$AD$8 -> 1 | AG18: Volume [m3] | AH18: =AH8/$AI$8 -> 0.70813066 | AI18: =AI8/$AI$8 -> 1
C19: Power Discharge [kW] | D19: =D9/$E$9 -> 0.49865591 | E19: =E9/$E$9 -> 1 | F19: =F9/$E$9 -> 0.86021505 | G19: =G9/$E$9 -> 0.78629032 | K19: Power Discharge [kW] | L19: =L9/$L$9 -> 1 | M19: =M9/$L$9 -> 0.51020408 | N19: =N9/$L$9 -> 0.49659864 | O19: =O9/$L$9 -> 0.66893424 | S19: Power Discharge [kW] | T19: =T9/$T$9 -> 1 | U19: =U9/$T$9 -> 0.4999831 | V19: =V9/$T$9 -> 0.95734406 | W19: =W9/$T$9 -> 0.81910905 | AA19: Power Discharge [kW] | AB19: =AB9/$AC$9 -> 0.59491525 | AC19: =AC9/$AC$9 -> 1 | AD19: =AD9/$AC$9 -> 0.62099573 | AG19: Power Discharge [kW] | AH19: =AH9/$AI$9 -> 0.59491525 | AI19: =AI9/$AI$9 -> 1
