Workbook

Sheet 1m_25%
C5: Battery Sizing
A6: Pot _ 100% [kW] | B6: Use Time | C6: Time | D6: Pot [%] | E6: Pot_nom[kW] | F6: Energy Batt [kWh]
A7: 3650 | B7: 0.5 | C7: 8 | D7: 0 | E7: =2*1825*D7 -> 0 | F7: =E7*$B$7 -> 0
C8: 8.5 | D8: 0 | E8: =2*1825*D8 -> 0 | F8: =E8*$B$7 -> 0
C9: 9 | D9: 0.05 | E9: =2*1825*D9 -> 182.5 | F9: =E9*$B$7 -> 91.25 | G9: =(E9*1000)/780 -> 233.97436
C10: 9.5 | D10: 0.05 | E10: =2*1825*D10 -> 182.5 | F10: =E10*$B$7 -> 91.25
C11: 10 | D11: 0.25 | E11: =2*1825*D11 -> 912.5 | F11: =E11*$B$7 -> 456.25 | G11: =(E11*1000)/780 -> 1169.8718 | H11: =G11-G9 -> 935.89744
C12: 10.5 | D12: 0.25 | E12: =2*1825*D12 -> 912.5 | F12: =E12*$B$7 -> 456.25
C13: 11 | D13: 0.35 | E13: =2*1825*D13 -> 1277.5 | F13: 0
C14: 11.5 | D14: 0.55 | E14: =2*1825*D14 -> 2007.5 | F14: 0
C15: 12 | D15: 0.95 | E15: =2*1825*D15 -> 3467.5 | F15: 0
C16: 12.5 | D16: 0.55 | E16: =2*1825*D16 -> 2007.5 | F16: 0
C17: 13 | D17: 0.55 | E17: =2*1825*D17 -> 2007.5 | F17: 0
C18: 13.5 | D18: 0.35 | E18: =2*1825*D18 -> 1277.5 | F18: 0
C19: 14 | D19: 0.25 | E19: =2*1825*D19 -> 912.5 | F19: =E19*$B$7 -> 456.25
C20: 14.5 | D20: 0.25 | E20: =2*1825*D20 -> 912.5 | F20: =E20*$B$7 -> 456.25
C21: 15 | D21: 0.15 | E21: =2*1825*D21 -> 547.5 | F21: =E21*$B$7 -> 273.75 | G21: =(E21*1000)/780 -> 701.92308 | H21: =G21-G11 -> -467.94872
C22: 15.5 | D22: 0.15 | E22: =2*1825*D22 -> 547.5 | F22: =E22*$B$7 -> 273.75
C23: 16 | D23: 0.1 | E23: =2*1825*D23 -> 365 | F23: =E23*$B$7 -> 182.5 | G23: =(E23*1000)/780 -> 467.94872 | H23: =G23-G21 -> -233.97436
C24: 16.5 | D24: 0.1 | E24: =2*1825*D24 -> 365 | F24: =E24*$B$7 -> 182.5
C25: 17 | D25: 0.05 | E25: =2*1825*D25 -> 182.5 | F25: =E25*$B$7 -> 91.25 | G25: =(E25*1000)/780 -> 233.97436 | H25: =G25-G23 -> -233.97436
C26: 17.5 | D26: 0.05 | E26: =2*1825*D26 -> 182.5 | F26: =E26*$B$7 -> 91.25
C27: 18 | D27: 0 | E27: =2*1825*D27 -> 0 | F27: =E27*$B$7 -> 0
C28: Total | F28: =SUM(F7:F27) -> 3102.5

Sheet 2m_25%
A3: Pot _ 100% [kW] | B3: Use Time | C3: Time | D3: Pot [%] | E3: Pot [kW] | F3: Energy Batt [kWh]
A4: 3650 | B4: 0.5 | C4: 8 | D4: 0 | E4: =2*1825*D4 -> 0 | F4: =$B$4*E4 -> 0
C5: 8.5 | D5: 0.1 | E5: =2*1825*D5 -> 365 | F5: =$B$4*E5 -> 182.5 | G5: =(E5*1000)/780 -> 467.94872
C6: 9 | D6: 0.25 | E6: =2*1825*D6 -> 912.5 | F6: =$B$4*E6 -> 456.25 | G6: =(E6*1000)/780 -> 1169.8718 | H6: =G6-G5 -> 701.92308
C7: 9.5 | D7: 0.4 | E7: =2*1825*D7 -> 1460 | F7: 0
C8: 10 | D8: 0.95 | E8: =2*1825*D8 -> 3467.5 | F8: 0
C9: 10.5 | D9: 0.75 | E9: =2*1825*D9 -> 2737.5 | F9: 0
C10: 11 | D10: 0.35 | E10: =2*1825*D10 -> 1277.5 | F10: 0
C11: 11.5 | D11: 0.15 | E11: =2*1825*D11 -> 547.5 | F11: =$B$4*E11 -> 273.75 | G11: =(E11*1000)/780 -> 701.92308 | H11: =G11-G6 -> -467.94872
C12: 12 | D12: 0.05 | E12: =2*1825*D12 -> 182.5 | F12: =$B$4*E12 -> 91.25 | G12: =(E12*1000)/780 -> 233.97436 | H12: =G12-G11 -> -467.94872
C13: 12.5 | D13: 0 | E13: =2*1825*D13 -> 0 | F13: =$B$4*E13 -> 0
C14: 13 | D14: 0 | E14: =2*1825*D14 -> 0 | F14: =$B$4*E14 -> 0
C15: 13.5 | D15: 0 | E15: =2*1825*D15 -> 0 | F15: =$B$4*E15 -> 0
C16: 13.995357 | D16: 0.05 | E16: =2*1825*D16 -> 182.5 | F16: =$B$4*E16 -> 91.25
C17: 14.5 | D17: 0.15 | E17: =2*1825*D17 -> 547.5 | F17: =$B$4*E17 -> 273.75 | G17: =(E17*1000)/780 -> 701.92308 | H17: =G17-G12 -> 467.94872
C18: 14.995 | D18: 0.25 | E18: =2*1825*D18 -> 912.5 | F18: =$B$4*E18 -> 456.25 | G18: =(E18*1000)/780 -> 1169.8718 | H18: =G18-G17 -> 467.94872
C19: 15.5 | D19: 0.35 | E19: =2*1825*D19 -> 1277.5 | F19: 0
C20: 15.994643 | D20: 0.95 | E20: =2*1825*D20 -> 3467.5 | F20: 0
C21: 16.5 | D21: 0.7 | E21: =2*1825*D21 -> 2555 | F21: 0
C22: 16.994286 | D22: 0.45 | E22: =2*1825*D22 -> 1642.5 | F22: 0
C23: 17.5 | D23: 0.3 | E23: =2*1825*D23 -> 1095 | F23: 0
C24: 17.993929 | D24: 0 | E24: =2*1825*D24 -> 0 | F24: =$B$4*E24 -> 0
C25: Total | F25: =SUM(F4:F24) -> 1825

Sheet EnergyDemand_25%
C4: E_load | D4: Energy Required by the load profile (kWh) | E4: ='1m_25%'!F28+192 -> 3294.5 | G4: P_batt (kW) | H4: 1000
C5: k_aging | D5: Battery Aging factor (over-sizing for end-of-life) (%) | E5: 0.8 | G5: C-rate | H5: =H4/E4 -> 0.3035362
C6: DOD_max | D6: Maximum allowable Depth of Discharge (%) | E6: 0.8
C7: n_sys | D7: System efficiency (path from the battery to propeller) (%) | E7: 0.88
C8: k_temp | D8: Temperature correction factor (-) | E8: 1.05
C9: k_c-rate | D9: Capacity rating factor (-) | E9: 1
C10: E_de | D10: Equivalent Energy Demand (kWh) | E10: =(E4*E8*E9)/(E7*E6*E5) -> 6142.0898
C13: E_batt_out | E13: =3300/E7 -> 3750
C14: E_BOL | E14: =E13/E6 -> 4687.5
C15: E_EOL | E15: =E14/E5 -> 5859.375
C16: E_final | E16: =E15*E9*E8 -> 6152.3438

Sheet NMC
C3: Batería | D3: ABL-012010P | F3: Batería | G3: ABL-012030P | I3: Batería | J3: E4050T1 | L3: Baterías NMC (LiNiMnCo02)
C4: Marca | D4: Aegis Battery | F4: Marca | G4: Aegis Battery | I4: Marca | J4: Corvus Energy | M4: AEGIS1 | N4: AEGIS2 | O4: Corvus Energy | P4: Avg
C5: Tecnología | D5: NMC | F5: Tecnología | G5: NMC | I5: Tecnología | J5: NMC | L5: Ciclos de Vida | M5: =1000 -> 1000 | N5: =1000 -> 1000 | O5: =2000 -> 2000 | P5: =(M5+N5+O5)/3 -> 1333.3333
L6: Celdas Totales | M6: =D29 -> 52542 | N6: =G29 -> 17514 | O6: =J29 -> 14784 | P6: =(M6+N6+O6)/3 -> 28280
C7: Energy Density [Wh/kg] | D7: =D10/D8 -> 150 | F7: Energy Density [Wh/kg] | G7: =G10/G8 -> 171.42857 | I7: Energy Density [Wh/kg] | J7: =J23/J8 -> 891.7298 | L7: Specific energy [Wh/kg] | M7: =D7 -> 150 | N7: =G7 -> 171.42857 | O7: =J7 -> 891.7298 | P7: =(M7+N7+O7)/3 -> 404.38612
C8: Weight [kg] | D8: 0.8 | F8: Weight [kg] | G8: 2.1 | I8: Weight [kg] | J8: 0.48 | L8: Volume density [Wh/L] | M8: =D9 -> 244.89796 | N8: =G9 -> 319.43212 | O8: =J9 -> 225.12507 | P8: =(M8+N8+O8)/3 -> 263.15172
C9: Energy Density [Wh/L] | D9: =D10/D15 -> 244.89796 | F9: Energy Density [Wh/L] | G9: =G10/G15 -> 319.43212 | I9: Energy Density [Wh/L] | J9: =J23/J15 -> 225.12507 | L9: Power Discharge [kW] | M9: =D50/1000 -> 3.1275 | N9: =G50/1000 -> 6.255 | O9: =J50/1000 -> 5.376 | P9: =(M9+N9+O9)/3 -> 4.9195
C10: Energy [Wh] | D10: 120 | F10: Energy [Wh] | G10: 360
C12: Length [mm] | D12: 100 | F12: Length [mm] | G12: 230
C13: Width [mm] | D13: 70 | F13: Width [mm] | G13: 70
C14: Thickness [mm] | D14: 70 | F14: Thickness [mm] | G14: 70
C15: Volume [L] | D15: =1000*D12*D13*D14/1000000000 -> 0.49 | F15: Volume [L] | G15: =1000*G12*G13*G14/1000000000 -> 1.127 | I15: Volume [L] | J15: 1.9013
C19: Batería | F19: Batería | I19: Batería
C20: Ubp [V] (Battery pack voltage) | D20: 750 | F20: Ubp [V] (Battery pack voltage) | G20: 750 | I20: Ubp [V] (Battery pack voltage) | J20: 750
C21: Ubc [V] (Baterry cell voltage) | D21: 12 | F21: Ubc [V] (Baterry cell voltage) | G21: 12 | I21: Ubc [V] (Baterry cell voltage) | J21: =J20/J22 -> 2.8409091
C22: Nsc [-] (Number of cell in string) | D22: =ROUNDUP(D20/D21,0) -> 63 | F22: Nsc [-] (Number of cell in string) | G22: =ROUNDUP(G20/G21,0) -> 63 | I22: Nsc [-] (Number of cell in string) | J22: 264
C23: Ebc [Wh] (Energy of a baterry cell) | D23: =D10 -> 120 | F23: Ebc [Wh] (Energy of a baterry cell) | G23: =G10 -> 360 | I23: Ebc [Wh] (Energy of a baterry cell) | J23: =J24/J22 -> 428.0303
C24: Ebs [Wh] (Energy of a String) | D24: =D23*D22 -> 7560 | F24: Ebs [Wh] (Energy of a String) | G24: =G23*G22 -> 22680 | I24: Ebs [Wh] (Energy of a String) | J24: =226000/2 -> 113000
C25: Ebp [Wh] (Battery pack total energy) | D25: 6300000 | F25: Ebp [Wh] (Battery pack total energy) | G25: 6300000 | I25: Ebp [Wh] (Battery pack total energy) | J25: 6300000
C26: Nsb [-] (Number of strings in a battery pack) | D26: =ROUNDUP(D25/D24,0) -> 834 | F26: Nsb [-] (Number of strings in a battery pack) | G26: =ROUNDUP(G25/G24,0) -> 278 | I26: Nsb [-] (Number of strings in a battery pack) | J26: =ROUNDUP(J25/J24,0) -> 56
C27: Cbc [Ah] (Battery cell capacity) | D27: 10 | F27: Cbc [Ah] (Battery cell capacity) | G27: 30 | I27: Cbc [Ah] (Battery cell capacity) | J27: 128
C28: Cbp [Ah] (Battery pack capacity) | D28: =D27*D26 -> 8340 | F28: Cbp [Ah] (Battery pack capacity) | G28: =G27*G26 -> 8340 | I28: Cbp [Ah] (Battery pack capacity) | J28: =J27*J26 -> 7168
C29: Nbp [-] (Number of cells of the battery pack) | D29: =D22*D26 -> 52542 | F29: Nbp [-] (Number of cells of the battery pack) | G29: =G22*G26 -> 17514 | I29: Nbp [-] (Number of cells of the battery pack) | J29: =J22*J26 -> 14784
C31: mbc [kg] (mass of each battery cell) | D31: =D8 -> 0.8 | F31: mbc [kg] (mass of each battery cell) | G31: =G8 -> 2.1 | I31: mbc [kg] (mass of each battery cell) | J31: =J8 -> 0.48
C32: mbp [kg] (battery mass pack) | D32: =D29*D31 -> 42033.6 | F32: mbp [kg] (battery mass pack) | G32: =G29*G31 -> 36779.4 | I32: mbp [kg] (battery mass pack) | J32: =J31*J29 -> 7096.32
C33: Vbc [m3] (volume of each cell) | D33: =D15/1000 -> 0.00049 | F33: Vbc [m3] (volume of each cell) | G33: =G15/1000 -> 0.001127 | I33: Vbc [m3] (volume of each cell) | J33: =J15/1000 -> 0.0019013
C34: Vbp [m3] (volume of the battery pack) | D34: =D29*D33 -> 25.74558 | F34: Vbp [m3] (volume of the battery pack) | G34: =G29*G33 -> 19.738278 | I34: Vbp [m3] (volume of the battery pack) | J34: =J33*J29 -> 28.108819
C36: C-rate_bcc[1/h] (continuous C-rate of the battery cell)(charge) | D36: 0.5 | F36: C-rate_bcc[1/h] (continuous C-rate of the battery cell)(charge) | G36: 0.5 | I36: C-rate_bcc[1/h] (continuous C-rate of the battery cell)(charge) | J36: 1
C37: C-rate_bcc[1/h] (continuous C-rate of the battery cell)(discharge) | D37: 1 | F37: C-rate_bcc[1/h] (continuous C-rate of the battery cell)(discharge) | G37: 1 | I37: C-rate_bcc[1/h] (continuous C-rate of the battery cell)(discharge) | J37: 1
C38: C-rate_bcp[1/h] (peak C-rate of the battery cell) | D38: 3 | F38: C-rate_bcp[1/h] (peak C-rate of the battery cell) | G38: 3 | I38: C-rate_bcp[1/h] (peak C-rate of the battery cell) | J38: 3
C39: Charge Current [A] | D39: 3 | F39: Charge Current [A] | G39: 5 | I39: Charge Current [A] | J39: =J27*J36 -> 128
C40: Constant Discharge Current [A] | D40: 5 | F40: Constant Discharge Current [A] | G40: 30 | I40: Constant Discharge Current [A] | J40: =J37*J27 -> 128
C41: Peak Discharge Current [A] @2s | D41: 20 | F41: Peak Discharge Current [A] @2s | G41: 60 | I41: Peak Discharge Current [A] @2s | J41: 750
C42: Ispc [A] (string peak current) | D42: =D41 -> 20 | F42: Ispc [A] (string peak current) | G42: =G41 -> 60 | I42: Ispc [A] (string peak current) | J42: =J41 -> 750
C43: Ibpp[A] (battery pack pack current) | D43: =D42*D26 -> 16680 | F43: Ibpp[A] (battery pack pack current) | G43: =G42*G26 -> 16680 | I43: Ibpp[A] (battery pack pack current) | J43: =J42*J26 -> 42000
C44: Pbpp [kW] (battery pack peak power) | D44: =D43*D20/1000 -> 12510 | F44: Pbpp [kW] (battery pack peak power) | G44: =G43*G20/1000 -> 12510 | I44: Pbpp [kW] (battery pack peak power) | J44: =J43*J20/1000 -> 31500
C45: Iscc [A] (string continuous current) (charge) | D45: =D39 -> 3 | F45: Iscc [A] (string continuous current) (charge) | G45: =G39 -> 5 | I45: Iscc [A] (string continuous current) (charge) | J45: =J39 -> 128
C46: Ibpc[A] (battery pack continuous current) (charge) | D46: =D45*D26 -> 2502 | F46: Ibpc[A] (battery pack continuous current) (charge) | G46: =G45*G26 -> 1390 | I46: Ibpc[A] (battery pack continuous current) (charge) | J46: =J45*J26 -> 7168
C47: Pbpc[W] (battery pack continuous power) (charge) | D47: =D46*D20 -> 1876500 | F47: Pbpc[W] (battery pack continuous power) (charge) | G47: =G46*G20 -> 1042500 | I47: Pbpc[W] (battery pack continuous power) (charge) | J47: =J46*J20 -> 5376000
C48: Iscc [A] (string continuous current) (discharge) | D48: =D40 -> 5 | F48: Iscc [A] (string continuous current) (discharge) | G48: =G40 -> 30 | I48: Iscc [A] (string continuous current) (discharge) | J48: =J40 -> 128
...

Sheet LFP
T2: Baterías LFP (LiFePO4)
C3: Batería | D3: URB1270 | G3: Batería | H3: PSL-SC-12500 | K3: Batería | L3: U27-36XP | U3: Ultralife | V3: PowerSonic | W3: Valence | X3: Promedio LFP
C4: Marca | D4: Ultralife | G4: Marca | H4: PowerSonic | K4: Marca | L4: Valence | T4: Ciclos de Vida | U4: 1500 | V4: 2000 | W4: 4000 | X4: =(U4+V4+W4)/3 -> 2500
C5: Tecnología | D5: LFP | G5: Tecnología | H5: LFP | K5: Tecnología | L5: LFP | T5: Celdas | U5: =D29 -> 64959 | V5: =H29 -> 9853 | W5: =L29 -> 3300 | X5: =(U5+V5+W5)/3 -> 26037.333
T6: Specific energy [Wh/kg] | U6: =D7 -> 97 | V6: =H7 -> 101.5873 | W6: =L7 -> 102 | X6: =(U6+V6+W6)/3 -> 100.19577
C7: Energy Density [Wh/kg] | D7: 97 | G7: Energy Density [Wh/kg] | H7: =H11/H8 -> 101.5873 | K7: Energy Density [Wh/kg] | L7: 102 | T7: Volume density [Wh/L] | U7: 107 | V7: =640/H15 -> 114.44835 | W7: =L11/L15 -> 162.13204 | X7: =(U7+V7+W7)/3 -> 127.86013
C8: Battery Cell Weight min [kg] | D8: 0.9 | G8: Battery Cell Weight [kg] | H8: 6.3 | K8: Battery Cell Weight [kg] | L8: 18.7 | T8: Power Discharge [kW] | U8: =D50 -> 12386.25 | V8: =H50 -> 6262.5 | W8: =L50 -> 6187.5 | X8: =(U8+V8+W8)/3 -> 8278.75
C9: Battery Cell Weight max [kg] | D9: 1.1
C10: Energy min [Wh] | D10: =D7*D8 -> 87.3
C11: Energy max [Wh] | D11: =D7*D9 -> 106.7 | G11: Energy [Wh] | H11: 640 | K11: Energy [Wh] | L11: 1920 | O11: Motor Main Diesel Cat3516B
C12: Length [mm] | D12: 152 | G12: Length [mm] | H12: 197 | K12: Length [mm] | L12: 306 | O12: Dim A (mm) | P12: 5957
C13: Width [mm] | D13: 65 | G13: Width [mm] | H13: 166 | K13: Width [mm] | L13: 172 | O13: Dim B (mm) | P13: 2286
C14: Thickness [mm] | D14: 92 | G14: Thickness [mm] | H14: 171 | K14: Thickness [mm] | L14: 225 | O14: Dim C (mm) | P14: 2494
C15: Volume [m3] | D15: =D12*D13*D14/1000000000 -> 0.00090896 | G15: Volume [L] | H15: =1000*H12*H13*H14/(1000000000) -> 5.592042 | K15: Volume [L] | L15: =1000*L12*L13*L14/(1000000000) -> 11.8422 | O15: Vdiesel (mm3) | P15: =P12*P13*P14 -> 33962548788
O16: Vdiesel (m3) | P16: 33.963
O17: Vdiesel (L) | P17: 33963
O18: mdiesel (kg) | P18: 13750
C19: Batería | G19: Batería | K19: Batería
C20: Ubp [V] (Battery pack voltage) | D20: 750 | G20: Ubp [V] (Battery pack voltage) | H20: 750 | K20: Ubp [V] (Battery pack voltage) | L20: 750 | O20: Battery Pack DAMEN ASD TUG 2810
C21: Ubc [V] (Baterry cell voltage) | D21: 12.8 | G21: Ubc [V] (Baterry cell voltage) | H21: 12.8 | K21: Ubc [V] (Baterry cell voltage) | L21: 38.4 | O21: Total number | P21: 140
C22: Nsc [-] (Number of cell in string) | D22: =ROUNDUP(D20/D21,0) -> 59 | G22: Nsc [-] (Number of cell in string) | H22: =ROUNDUP(H20/H21,0) -> 59 | K22: Nsc [-] (Number of cell in string) | L22: =ROUNDUP(L20/L21,0) -> 20 | O22: Vbatt (L) | P22: =P21*L15 -> 1657.908
C23: Ebc [Wh] (Energy of a baterry cell) | D23: 97 | G23: Ebc [Wh] (Energy of a baterry cell) | H23: =H11 -> 640 | K23: Ebc [Wh] (Energy of a baterry cell) | L23: =L11 -> 1920 | O23: mbatt( kg) | P23: =P21*L8 -> 2618
C24: Ebs [Wh] (Energy of a String) | D24: =D23*D22 -> 5723 | G24: Ebs [Wh] (Energy of a String) | H24: =H23*H22 -> 37760 | K24: Ebs [Wh] (Energy of a String) | L24: =L23*L22 -> 38400 | O24: Gen Set
C25: Ebp [Wh] (Battery pack total energy) | D25: 6300000 | G25: Ebp [Wh] (Battery pack total energy) | H25: 6300000 | K25: Ebp [Wh] (Battery pack total energy) | L25: 6300000 | O25: mgenset( kg) | P25: 2600
C26: Nsb [-] (Number of strings in a battery pack) | D26: =ROUNDUP(D25/D24,0) -> 1101 | G26: Nsb [-] (Number of strings in a battery pack) | H26: =ROUNDUP(H25/H24,0) -> 167 | K26: Nsb [-] (Number of strings in a battery pack) | L26: =ROUNDUP(L25/L24,0) -> 165 | O26: Vbatt (L) | P26: 3801.63
C27: Cbc [Ah] (Battery cell capacity) | D27: 7.6 | G27: Cbc [Ah] (Battery cell capacity) | H27: 50 | K27: Cbc [Ah] (Battery cell capacity) | L27: 50
C28: Cbp [Ah] (Battery pack capacity) | D28: =D27*D26 -> 8367.6 | G28: Cbp [Ah] (Battery pack capacity) | H28: =H27*H26 -> 8350 | K28: Cbp [Ah] (Battery pack capacity) | L28: =L27*L26 -> 8250 | O28: Rupanco TUG
C29: Nbp [-] (Number of cells of the battery pack) | D29: =D22*D26 -> 64959 | G29: Nbp [-] (Number of cells of the battery pack) | H29: =H22*H26 -> 9853 | K29: Nbp [-] (Number of cells of the battery pack) | L29: =L22*L26 -> 3300 | O29: Gross Tonnage (L) | P29: =269*2.832*1000 -> 761808
O30: Net Tonage (L) | P30: =P29*0.3 -> 228542.4
C31: mbc [kg] (mass of each battery cell) | D31: 1 | G31: mbc [kg] (mass of each battery cell) | H31: 6.3 | K31: mbc [kg] (mass of each battery cell) | L31: 18.7 | O31: Deadweight (kg) | P31: 220000
C32: mbp [kg] (battery mass pack) | D32: =D29*D31 -> 64959 | G32: mbp [kg] (battery mass pack) | H32: =H29*H31 -> 62073.9 | K32: mbp [kg] (battery mass pack) | L32: =L29*L31 -> 61710
C33: Vbc [m3] (volume of each cell) | D33: =D15 -> 0.00090896 | G33: Vbc [m3] (volume of each cell) | H33: =H15/1000 -> 0.005592042 | K33: Vbc [m3] (volume of each cell) | L33: =L15/1000 -> 0.0118422
C34: Vbp [m3] (volume of the battery pack) | D34: =D29*D33 -> 59.045133 | G34: Vbp [m3] (volume of the battery pack) | H34: =H29*H33 -> 55.09839 | K34: Vbp [m3] (volume of the battery pack) | L34: =L29*L33 -> 39.07926
C36: C-rate_bcc[1/h] (continuous C-rate of the battery cell)(charge) | D36: =D39/D27 -> 1 | G36: C-rate_bcc[1/h] (continuous C-rate of the battery cell)(charge) | H36: =H39/H27 -> 1 | K36: C-rate_bcc[1/h] (continuous C-rate of the battery cell)(charge) | L36: =L39/L27 -> 1
C37: C-rate_bcc[1/h] (continuous C-rate of the battery cell)(discharge) | D37: =D40/D27 -> 1.9736842 | G37: C-rate_bcc[1/h] (continuous C-rate of the battery cell)(discharge) | H37: =H40/H27 -> 1 | K37: C-rate_bcc[1/h] (continuous C-rate of the battery cell)(discharge) | L37: =L40/L27 -> 1
C38: C-rate_bcp[1/h] (peak C-rate of the battery cell) | D38: =D41/D27 -> 7.2368421 | G38: C-rate_bcp[1/h] (peak C-rate of the battery cell) | H38: =H41/H27 -> 2.8 | K38: C-rate_bcp[1/h] (peak C-rate of the battery cell) | L38: =L41/L27 -> 3
C39: Charge Current [A] | D39: 7.6 | G39: Charge Current [A] | H39: 50 | K39: Charge Current [A] | L39: 50
C40: Constant Discharge Current [A] | D40: 15 | G40: Constant Discharge Current [A] | H40: 50 | K40: Constant Discharge Current [A] | L40: 50
C41: Peak Discharge Current [A] @2s | D41: 55 | G41: Peak Discharge Current [A] @2s | H41: 140 | K41: Peak Discharge Current [A] @2s | L41: 150
C42: Ispc [A] (string peak current) | D42: =D41 -> 55 | G42: Ispc [A] (string peak current) | H42: =H41 -> 140 | K42: Ispc [A] (string peak current) | L42: =L41 -> 150
...

Sheet LTO
C3: Batería | D3: SLB12400L151 | G3: Batería | H3: SLB08115L140 | K3: Batería | L3: ELB 1500mAh LTO
C4: Marca | D4: Nichicon | G4: Marca | H4: Nichicon | K4: Marca | L4: Eco Lotithium Battery
C5: Tecnología | D5: LTO | G5: Tecnología | H5: LTO | K5: Tecnología | L5: LTO
K6: Energy Density [Wh/L] | L6: =L11/L15 -> 212.8906
C7: Energy Density [Wh/L] | D7: 73 | G7: Energy Density [Wh/L] | H7: 58 | K7: Energy Density [Wh/kg] | L7: =L11/L8 -> 78.26087
C8: Weight [kg] | D8: 0.09 | G8: Weight [kg] | H8: 0.0012 | K8: Weight [kg] | L8: 0.046
C9: Energy Density [Wh/kg] | D9: =D10/D8 -> 4 | G9: Energy Density [Wh/Kg] | H9: =H10/H8 -> 28
C10: Energy [Wh] | D10: 0.36 | G10: Energy [Wh] | H10: =2.4*14*0.001 -> 0.0336
K11: Energy [Wh] | L11: 3.6
C12: Diam [mm] | D12: 12.5 | G12: Diam [mm] | H12: 8 | K12: Radio [mm] | L12: =18.2/2 -> 9.1
C13: Height [mm] | D13: 40 | G13: Height [mm] | H13: 11.5 | K13: Height [mm] | L13: 65
C15: Volume [L] | D15: =PI()*(D12^2)*D13/1000000 -> 0.019634954 | G15: Volume [L] | H15: =PI()*(H12^2)*H13/1000000 -> 0.0023122122 | K15: Volume [L] | L15: =PI()*(L12^2)*L13/1000000 -> 0.016910094
C19: Batería | G19: Batería | K19: Batería
C20: Ubp [V] (Battery pack voltage) | D20: 750 | G20: Ubp [V] (Battery pack voltage) | H20: 750 | K20: Ubp [V] (Battery pack voltage) | L20: 750
C21: Ubc [V] (Baterry cell voltage) | D21: =2.4 -> 2.4 | G21: Ubc [V] (Baterry cell voltage) | H21: =2.4 -> 2.4 | K21: Ubc [V] (Baterry cell voltage) | L21: =2.3 -> 2.3
C22: Ncs [-] (Number of cell in string) | D22: =ROUNDUP(D20/D21,0) -> 313 | G22: Ncs [-] (Number of cell in string) | H22: =ROUNDUP(H20/H21,0) -> 313 | K22: Nsc [-] (Number of cell in string) | L22: =ROUNDUP(L20/L21,0) -> 327
C23: Ebc [Wh] (Energy of a baterry cell) | D23: =D10 -> 0.36 | G23: Ebc [Wh] (Energy of a baterry cell) | H23: =H10 -> 0.0336 | K23: Ebc [Wh] (Energy of a baterry cell) | L23: =L11 -> 3.6
C24: Ebs [Wh] (Energy of a String) | D24: =D23*D22 -> 112.68 | G24: Ebs [Wh] (Energy of a String) | H24: =H23*H22 -> 10.5168 | K24: Ebs [Wh] (Energy of a String) | L24: =L23*L22 -> 1177.2
C25: Ebp [Wh] (Battery pack total energy) | D25: 6300000 | G25: Ebp [Wh] (Battery pack total energy) | H25: 6300000 | K25: Ebp [Wh] (Battery pack total energy) | L25: 6300000
C26: Nsb [-] (Number of strings in a battery pack) | D26: =ROUNDUP(D25/D24,0) -> 55911 | G26: Nsb [-] (Number of strings in a battery pack) | H26: =ROUNDUP(H25/H24,0) -> 599042 | K26: Nsb [-] (Number of strings in a battery pack) | L26: =ROUNDUP(L25/L24,0) -> 5352
C27: Cbc [Ah] (Battery cell capacity) | D27: =0.15 -> 0.15 | G27: Cbc [Ah] (Battery cell capacity) | H27: =0.014 -> 0.014 | K27: Cbc [Ah] (Battery cell capacity) | L27: 1.5
C28: Cbp [Ah] (Battery pack capacity) | D28: =D27*D26 -> 8386.65 | G28: Cbp [Ah] (Battery pack capacity) | H28: =H27*H26 -> 8386.588 | K28: Cbp [Ah] (Battery pack capacity) | L28: =L27*L26 -> 8028
C29: Ncb [-] (Number of cells of the battery pack) | D29: =D22*D26 -> 17500143 | G29: Ncb [-] (Number of cells of the battery pack) | H29: =H22*H26 -> 187500146 | K29: Nbp [-] (Number of cells of the battery pack) | L29: =L22*L26 -> 1750104
C31: mbc [kg] (mass of each battery cell) | D31: =D8 -> 0.09 | G31: mbc [kg] (mass of each battery cell) | H31: 0.0012 | K31: mbc [kg] (mass of each battery cell) | L31: =L8 -> 0.046
C32: mbp [kg] (battery mass pack) | D32: =D29*D31 -> 1575012.9 | G32: mbp [kg] (battery mass pack) | H32: =H29*H31 -> 225000.18 | K32: mbp [kg] (battery mass pack) | L32: =L29*L31 -> 80504.784
C33: Vcc(pc) [m3] (volume of each cell) | D33: =10*D15/1000 -> 0.00019634954 | G33: Vcc(pc) [m3] (volume of each cell) | H33: =H15/1000 -> 2.3122122e-06 | K33: Vbc [m3] (volume of each cell) | L33: =L15/1000 -> 1.6910094e-05
C34: Vbp [m3] (volume of the battery pack) | D34: =D29*D33 -> 3436.145 | G34: Vbp [m3] (volume of the battery pack) | H34: =H29*H33 -> 433.54012 | K34: Vbp [m3] (volume of the battery pack) | L34: =L29*L33 -> 29.594423
C36: C-rate_bcc[1/h] (continuous C-rate of the battery cell)(charge) | D36: =D39/D27 -> 1 | G36: C-rate_bcc[1/h] (continuous C-rate of the battery cell)(charge) | H36: =H39/H27 -> 1 | K36: C-rate_bcc[1/h] (continuous C-rate of the battery cell)(charge) | L36: =L39/L27 -> 2
C37: C-rate_bcc[1/h] (continuous C-rate of the battery cell)(discharge) | D37: =D40/D27 -> 1 | G37: C-rate_bcc[1/h] (continuous C-rate of the battery cell)(discharge) | H37: =H40/H27 -> 0.5 | K37: C-rate_bcc[1/h] (continuous C-rate of the battery cell)(discharge) | L37: =L40/L27 -> 1
C38: C-rate_bcp[1/h] (peak C-rate of the battery cell) | D38: =D41/D27 -> 20 | G38: C-rate_bcp[1/h] (peak C-rate of the battery cell) | H38: =H41/H27 -> 20 | K38: C-rate_bcp[1/h] (peak C-rate of the battery cell) | L38: =L41/L27 -> 8
C39: Charge Current [A] | D39: =0.15 -> 0.15 | G39: Charge Current [A] | H39: =0.014 -> 0.014 | K39: Charge Current [A] | L39: =3 -> 3
C40: Constant Discharge Current [A] | D40: =0.15 -> 0.15 | G40: Constant Discharge Current [A] | H40: =0.007 -> 0.007 | K40: Constant Discharge Current [A] | L40: =1.5 -> 1.5
C41: Peak Discharge Current [A] @ 1s | D41: =3 -> 3 | G41: Peak Discharge Current [A] @ 1s | H41: =0.28 -> 0.28 | K41: Peak Discharge Current [A] @2s | L41: =12 -> 12
C42: Ispc [A] (string peak current) | D42: =D41 -> 3 | G42: Ispc [A] (string peak current) | H42: =H41 -> 0.28 | K42: Ispc [A] (string peak current) | L42: =L41 -> 12
C43: Ibpp[A] (battery pack pack current) | D43: =D42*D26 -> 167733 | E43: =D43/1000 -> 167.733 | G43: Ibpp[A] (battery pack pack current) | H43: =H42*H26 -> 167731.76 | I43: =H43/1000 -> 167.73176 | K43: Ibpp[A] (battery pack pack current) | L43: =L42*L26 -> 64224 | M43: =L43/1000 -> 64.224
C44: Pbpp [kW] (battery pack peak power) | D44: =D43*D20/1000 -> 125799.75 | E44: =D44/1000 -> 125.79975 | G44: Pbpp [kW] (battery pack peak power) | H44: =H43*H20/1000 -> 125798.82 | I44: =H44/1000 -> 125.79882 | K44: Pbpp [kW] (battery pack peak power) | L44: =L43*L20/1000 -> 48168 | M44: =L44/1000 -> 48.168
C45: Iscc [A] (string continuous current) (charge) | D45: =D39 -> 0.15 | G45: Iscc [A] (string continuous current) (charge) | H45: =H39 -> 0.014 | K45: Iscc [A] (string continuous current) (charge) | L45: =L39 -> 3
C46: Ibpc[A] (battery pack continuous current) (charge) | D46: =D45*D26 -> 8386.65 | G46: Ibpc[A] (battery pack continuous current) (charge) | H46: =H45*H26 -> 8386.588 | K46: Ibpc[A] (battery pack continuous current) (charge) | L46: =L45*L26 -> 16056
C47: Pbpc[kW] (battery pack continuous power) (charge) | D47: =D46*D20/1000 -> 6289.9875 | G47: Pbpc[kW] (battery pack continuous power) (charge) | H47: =H46*H20/1000 -> 6289.941 | K47: Pbpc[W] (battery pack continuous power) (charge) | L47: =L46*L20/1000 -> 12042
C48: Iscc [A] (string continuous current) (discharge) | D48: =D40 -> 0.15 | G48: Iscc [A] (string continuous current) (discharge) | H48: =H40 -> 0.007 | K48: Iscc [A] (string continuous current) (discharge) | L48: =L40 -> 1.5
...

Sheet Radar_Plot
C3: Baterías NMC (LiNiMnCo02) | K3: Baterías LFP (LiFePO4) | S3: Baterías LTO (Li2TiO3) | AA3: Baterías Ion Litio | AI3: Baterías Ion Litio
D4: AEGIS1 | E4: AEGIS2 | F4: Corvus Energy | G4: NMC | L4: Ultralife | M4: PowerSonic | N4: Valence | O4: LFP | T4: Nichicon 1 | U4: Nichicon 2 | V4: ECO Lithium | W4: LTO | AB4: NMC | AC4: LFP | AD4: LTO | AE4: Avg | AJ4: NMC | AK4: LFP | AL4: Avg
C5: Ciclos de Vida | D5: 1000 | E5: 1000 | F5: 2000 | G5: =SUM(D5:F5)/3 -> 1333.3333 | K5: Ciclos de Vida | L5: 1500 | M5: 2000 | N5: 4000 | O5: =(L5+M5+N5)/3 -> 2500 | S5: Ciclos de Vida | T5: 20000 | U5: 10000 | V5: 10000 | W5: =SUM(T5:V5)/3 -> 13333.333 | AA5: Ciclos de Vida | AB5: =G5 -> 1333.3333 | AC5: =O5 -> 2500 | AD5: =W5 -> 13333.333 | AE5: =SUM(AB5:AD5)/3 -> 5722.2222 | AI5: Ciclos de Vida | AJ5: 1333 | AK5: 2500 | AL5: =SUM(AJ5:AK5)/2 -> 1916.5
C6: Celdas Totales | D6: =NMC!D29 -> 52542 | E6: =NMC!G29 -> 17514 | F6: =NMC!J29 -> 14784 | G6: =SUM(D6:F6)/3 -> 28280 | K6: Celdas Totales | L6: =LFP!D29 -> 64959 | M6: =LFP!H29 -> 9853 | N6: =LFP!L29 -> 3300 | O6: =(L6+M6+N6)/3 -> 26037.333 | S6: Celdas Totales | T6: =LTO!D29 -> 17500143 | U6: =LTO!H29 -> 187500146 | V6: =LTO!L29 -> 1750104 | W6: =SUM(T6:V6)/3 -> 68916798 | AA6: Celdas Totales | AB6: =G6 -> 28280 | AC6: =O6 -> 26037.333 | AD6: =W6 -> 68916798 | AE6: =SUM(AB6:AD6)/3 -> 22990372 | AI6: Celdas Totales | AJ6: 28280 | AK6: 26037.333 | AL6: =SUM(AJ6:AK6)/2 -> 27158.667
C7: Weight [kg] | D7: =NMC!D32 -> 42033.6 | E7: =NMC!G32 -> 36779.4 | F7: =NMC!J32 -> 7096.32 | G7: =SUM(D7:F7)/3 -> 28636.44 | K7: Weight [kg] | L7: =LFP!D32 -> 64959 | M7: =LFP!H32 -> 62073.9 | N7: =LFP!L32 -> 61710 | O7: =(L7+M7+N7)/3 -> 62914.3 | S7: Weight [kg] | T7: =LTO!D32 -> 1575012.9 | U7: =LTO!H32 -> 225000.18 | V7: =LTO!L32 -> 80504.784 | W7: =SUM(T7:V7)/3 -> 626839.28 | AA7: Weight [kg] | AB7: =G7 -> 28636.44 | AC7: =O7 -> 62914.3 | AD7: =W7 -> 626839.28 | AE7: =SUM(AB7:AD7)/3 -> 239463.34 | AI7: Weight [kg] | AJ7: 28636.44 | AK7: 62914.3 | AL7: =SUM(AJ7:AK7)/2 -> 45775.37
C8: Volume [m3] | D8: =NMC!D34 -> 25.74558 | E8: =NMC!G34 -> 19.738278 | F8: =NMC!J34 -> 28.108819 | G8: =SUM(D8:F8)/3 -> 24.530892 | K8: Volume [m3] | L8: =LFP!D34 -> 59.045133 | M8: =LFP!H34 -> 55.09839 | N8: =LFP!L34 -> 39.07926 | O8: =(L8+M8+N8)/3 -> 51.074261 | S8: Volume [m3] | T8: =LTO!D34 -> 3436.145 | U8: =LTO!H34 -> 433.54012 | V8: =LTO!L34 -> 29.594423 | W8: =SUM(T8:V8)/3 -> 1299.7599 | AA8: Volume [m3] | AB8: =G8 -> 24.530892 | AC8: =O8 -> 51.074261 | AD8: =W8 -> 1299.7599 | AE8: =SUM(AB8:AD8)/3 -> 458.45501 | AI8: Volume [m3] | AJ8: 24.530892 | AK8: 51.074261 | AL8: =SUM(AJ8:AK8)/2 -> 37.802577
C9: Power Discharge [kW] | D9: =NMC!D50 -> 3127.5 | E9: =NMC!G50 -> 6255 | F9: =NMC!J50 -> 5376 | G9: =SUM(D9:F9)/3 -> 4919.5 | K9: Power Discharge [kW] | L9: =LFP!D50 -> 12386.25 | M9: =LFP!H50 -> 6262.5 | N9: =LFP!L50 -> 6187.5 | O9: =(L9+M9+N9)/3 -> 8278.75 | S9: Power Discharge [kW] | T9: =LTO!D50 -> 6289.9875 | U9: =LTO!H50 -> 3144.9705 | V9: =LTO!L50 -> 6021 | W9: =SUM(T9:V9)/3 -> 5151.986 | AA9: Power Discharge [kW] | AB9: =G9 -> 4919.5 | AC9: =O9 -> 8278.75 | AD9: =W9 -> 5151.986 | AE9: =SUM(AB9:AD9)/3 -> 6116.7453 | AI9: Power Discharge [kW] | AJ9: 4919.5 | AK9: 8278.75 | AL9: =SUM(AJ9:AK9)/2 -> 6599.125
C13: Porcentajes Baterías NMC (LiNiMnCo02) | K13: Porcentajes Baterías LFP (LiFePO4) | S13: Porcentajes Baterías LTO (Li2TiO3) | AA13: Baterías Ion Litio | AI13: Baterías Ion Litio
D14: AEGIS1 | E14: AEGIS2 | F14: Corvus Energy | G14: NMC | L14: Ultralife | M14: PowerSonic | N14: Valence | O14: LFP | T14: Nichicon 1 | U14: Nichicon 2 | V14: ECO Lithium | W14: LTO | AB14: NMC | AC14: LFP | AD14: LTO | AE14: Avg | AJ14: NMC | AK14: LFP | AL14: Avg
C15: Ciclos de Vida | D15: =D5/$F$5 -> 0.5 | E15: =E5/$F$5 -> 0.5 | F15: =F5/$F$5 -> 1 | G15: =G5/$F$5 -> 0.66666667 | K15: Ciclos de Vida | L15: =L5/$N$5 -> 0.375 | M15: =M5/$N$5 -> 0.5 | N15: =N5/$N$5 -> 1 | O15: =O5/$N$5 -> 0.625 | S15: Ciclos de Vida | T15: =20000/20000 -> 1 | U15: =10000/20000 -> 0.5 | V15: =10000/20000 -> 0.5 | W15: =13333.3333333333/20000 -> 0.66666667 | AA15: Ciclos de Vida | AB15: =AB5/$AD$5 -> 0.1 | AC15: =AC5/$AD$5 -> 0.1875 | AD15: =AD5/$AD$5 -> 1 | AI15: Ciclos de Vida | AJ15: =AJ5/$AK$5 -> 0.5332 | AK15: =AK5/$AK$5 -> 1 | AL15: =AL5/$AK$5 -> 0.7666
C16: Celdas Totales | D16: =D6/$D$6 -> 1 | E16: =E6/$D$6 -> 0.33333333 | F16: =F6/$D$6 -> 0.2813749 | G16: =G6/$D$6 -> 0.53823608 | K16: Celdas Totales | L16: =L6/$L$6 -> 1 | M16: =M6/$L$6 -> 0.15168029 | N16: =N6/$L$6 -> 0.050801275 | O16: =O6/$L$6 -> 0.40082719 | S16: Celdas Totales | T16: =139612/1491644 -> 0.093596059 | U16: =1491644/1491644 -> 1 | V16: =55680/1491644 -> 0.037327942 | W16: =562312/1491644 -> 0.37697467 | AA16: Celdas Totales | AB16: =AB6/$AD$6 -> 0.00041034989 | AC16: =AC6/$AD$6 -> 0.00037780823 | AD16: =AD6/$AD$6 -> 1 | AI16: Celdas Totales | AJ16: =AJ6/$AJ$6 -> 1 | AK16: =AK6/$AJ$6 -> 0.92069778 | AL16: =AL6/$AJ$6 -> 0.96034889
C17: Weight [kg] | D17: =D7/$D$7 -> 1 | E17: =E7/$D$7 -> 0.875 | F17: =F7/$D$7 -> 0.16882494 | G17: =G7/$D$7 -> 0.68127498 | K17: Weight [kg] | L17: =L7/$L$7 -> 1 | M17: =M7/$L$7 -> 0.95558583 | N17: =N7/$L$7 -> 0.94998384 | O17: =O7/$L$7 -> 0.96852322 | S17: Specific energy [Wh/kg] | T17: =15.9261294244483/111.756922663701 -> 0.14250687 | U17: =111.756922663701/111.756922663701 -> 1 | V17: =78.2608695652174/111.756922663701 -> 0.7002776 | W17: =68.6479738844555/111.756922663701 -> 0.61426149 | AA17: Weight [kg] | AB17: =AB7/$AD$7 -> 0.045683864 | AC17: =AC7/$AD$7 -> 0.10036751 | AD17: =AD7/$AD$7 -> 1 | AI17: Weight [kg] | AJ17: =AJ7/$AK$7 -> 0.45516584 | AK17: =AK7/$AK$7 -> 1 | AL17: =AL7/$AK$7 -> 0.72758292
C18: Volume [m3] | D18: =D8/$F$8 -> 0.91592535 | E18: =E8/$F$8 -> 0.70220943 | F18: =F8/$F$8 -> 1 | G18: =G8/$F$8 -> 0.87271159 | K18: Volume [m3] | L18: =L8/$L$8 -> 1 | M18: =M8/$L$8 -> 0.93315719 | N18: =N8/$L$8 -> 0.66185405 | O18: =O8/$L$8 -> 0.86500374 | S18: Volume density [Wh/L] | T18: =T7/$T$7 -> 1 | U18: =U7/$T$7 -> 0.14285609 | V18: =V7/$T$7 -> 0.051113731 | W18: =W7/$T$7 -> 0.39798994 | AA18: Volume [m3] | AB18: =AB8/$AD$8 -> 0.018873404 | AC18: =AC8/$AD$8 -> 0.039295152 | AD18: =AD8/$AD$8 -> 1 | AI18: Volume [m3] | AJ18: =AJ8/$AK$8 -> 0.48029853 | AK18: =AK8/$AK$8 -> 1 | AL18: =AL8/$AK$8 -> 0.74014927
C19: Power Discharge [kW] | D19: =D9/$E$9 -> 0.5 | E19: =E9/$E$9 -> 1 | F19: =F9/$E$9 -> 0.85947242 | G19: =G9/$E$9 -> 0.78649081 | K19: Power Discharge [kW] | L19: =L9/$L$9 -> 1 | M19: =M9/$L$9 -> 0.50560097 | N19: =N9/$L$9 -> 0.49954587 | O19: =O9/$L$9 -> 0.66838228 | S19: Power Discharge [kW] | T19: =T9/$T$9 -> 1 | U19: =U9/$T$9 -> 0.4999963 | V19: =V9/$T$9 -> 0.95723561 | W19: =W9/$T$9 -> 0.8190773 | AA19: Power Discharge [kW] | AB19: =AB9/$AC$9 -> 0.59423222 | AC19: =AC9/$AC$9 -> 1 | AD19: =AD9/$AC$9 -> 0.62231448 | AI19: Power Discharge [kW] | AJ19: =AJ9/$AK$9 -> 0.59423222 | AK19: =AK9/$AK$9 -> 1 | AL19: =AL9/$AK$9 -> 0.79711611
